Workbook

Sheet Raw Data Unadj
E1: *all are unadj
B2: Ticker | C2: Date | D2: Open | E2: Close | F2: Event | H2: Ticker | I2: Date | J2: Open | K2: Close | L2: Event | N2: Ticker | O2: Date | P2: Open | Q2: Close | R2: Event | T2: Ticker | U2: Date | V2: Open | W2: Close | X2: Event | Z2: Ticker | AA2: Date | AB2: Open | AC2: Close | AD2: Event | AF2: Ticker | AG2: Date | AH2: Open | AI2: Close | AJ2: Event | AL2: Ticker | AM2: Date | AN2: Open | AO2: Close | AP2: Event | AR2: Ticker | AS2: Date | AT2: Open | AU2: Close | AV2: Event | AX2: Ticker | AY2: Date | AZ2: Open | BA2: Close | BB2: Event | BD2: Ticker | BE2: Date | BF2: Open | BG2: Close | BH2: Event
B3: MU | C3: 44200 | D3: 76.48 | E3: 74.05 | H3: NVDA | I3: 44200 | J3: 13.1 | K3: 13.11 | N3: F | O3: 44200 | P3: 8.81 | Q3: 8.52 | T3: CAT | U3: 44200 | V3: 183 | W3: 182.15 | Z3: XOM | AA3: 44200 | AB3: 41.45 | AC3: 41.5 | AF3: JPM | AG3: 44200 | AH3: 127.5 | AI3: 125.87 | AL3: AAPL | AM3: 44200 | AN3: 133.52 | AO3: 129.41 | AR3: MSFT | AS3: 44200 | AT3: 222.53 | AU3: 217.69 | AX3: WMT | AY3: 44200 | AZ3: 48.1 | BA3: 48.84 | BD3: KO | BE3: 44200 | BF3: 54.27 | BG3: 52.76
C4: 44201 | D4: 76.44 | E4: 77.26 | I4: 44201 | J4: 13.1 | K4: 13.4 | O4: 44201 | P4: 8.47 | Q4: 8.65 | U4: 44201 | V4: 181.21 | W4: 183.64 | AA4: 44201 | AB4: 41.84 | AC4: 43.5 | AG4: 44201 | AH4: 124.99 | AI4: 125.65 | AJ4: 0.9 Dividend | AM4: 44201 | AN4: 128.89 | AO4: 131.01 | AS4: 44201 | AT4: 217.26 | AU4: 217.9 | AY4: 44201 | AZ4: 48.87 | BA4: 48.58 | BE4: 44201 | BF4: 52.33 | BG4: 52.18
C5: 44202 | D5: 76.36 | E5: 77.11 | I5: 44202 | J5: 13.22 | K5: 12.61 | O5: 44202 | P5: 8.79 | Q5: 8.84 | U5: 44202 | V5: 187.15 | W5: 193.86 | AA5: 44202 | AB5: 44.41 | AC5: 44.61 | AG5: 44202 | AH5: 129.88 | AI5: 131.55 | AM5: 44202 | AN5: 127.72 | AO5: 126.6 | AS5: 44202 | AT5: 212.17 | AU5: 212.25 | AY5: 44202 | AZ5: 48.36 | BA5: 48.89 | BE5: 44202 | BF5: 51.97 | BG5: 50.52
C6: 44203 | D6: 78.06 | E6: 79.11 | I6: 44203 | J6: 12.97 | K6: 13.34 | O6: 44203 | P6: 8.94 | Q6: 9.06 | U6: 44203 | V6: 196.85 | W6: 194.23 | AA6: 44203 | AB6: 45 | AC6: 44.96 | AG6: 44203 | AH6: 135.69 | AI6: 135.87 | AM6: 44203 | AN6: 128.36 | AO6: 130.92 | AS6: 44203 | AT6: 214.04 | AU6: 218.29 | AY6: 44203 | AZ6: 49.21 | BA6: 48.88 | BE6: 44203 | BF6: 50.09 | BG6: 49.96
C7: 44204 | D7: 82.54 | E7: 77.42 | I7: 44204 | J7: 13.36 | K7: 13.28 | O7: 44204 | P7: 9.1 | Q7: 9 | U7: 44204 | V7: 193.85 | W7: 194.26 | AA7: 44204 | AB7: 45.2 | AC7: 45.46 | AG7: 44204 | AH7: 135.97 | AI7: 136.02 | AM7: 44204 | AN7: 132.43 | AO7: 132.05 | AS7: 44204 | AT7: 218.68 | AU7: 219.62 | AY7: 44204 | AZ7: 48.96 | BA7: 48.88 | BE7: 44204 | BF7: 50.03 | BG7: 51.08
C8: 44207 | D8: 76.59 | E8: 78.67 | I8: 44207 | J8: 13.42 | K8: 13.62 | O8: 44207 | P8: 8.87 | Q8: 9.3 | U8: 44207 | V8: 191.56 | W8: 193.86 | AA8: 44207 | AB8: 45.04 | AC8: 46.84 | AG8: 44207 | AH8: 134.58 | AI8: 138.05 | AM8: 44207 | AN8: 129.19 | AO8: 128.98 | AS8: 44207 | AT8: 218.47 | AU8: 217.49 | AY8: 44207 | AZ8: 48.67 | BA8: 49.1 | BE8: 44207 | BF8: 50.62 | BG8: 50.2
C9: 44208 | D9: 79.19 | E9: 79.46 | I9: 44208 | J9: 13.75 | K9: 13.48 | O9: 44208 | P9: 9.3 | Q9: 9.78 | U9: 44208 | V9: 194.68 | W9: 197.54 | AA9: 44208 | AB9: 47.46 | AC9: 47.88 | AG9: 44208 | AH9: 139.44 | AI9: 140.22 | AM9: 44208 | AN9: 128.5 | AO9: 128.8 | AS9: 44208 | AT9: 216.5 | AU9: 214.93 | AY9: 44208 | AZ9: 49.67 | BA9: 49.66 | BE9: 44208 | BF9: 50.04 | BG9: 50.11
C10: 44209 | D10: 78.95 | E10: 79.91 | I10: 44209 | J10: 13.49 | K10: 13.53 | O10: 44209 | P10: 9.91 | Q10: 9.78 | U10: 44209 | V10: 198.79 | W10: 195.89 | AA10: 44209 | AB10: 48.53 | AC10: 48.42 | AG10: 44209 | AH10: 138.59 | AI10: 140.35 | AM10: 44209 | AN10: 128.76 | AO10: 130.89 | AS10: 44209 | AT10: 214.02 | AU10: 216.34 | AY10: 44209 | AZ10: 49.58 | BA10: 49.15 | BE10: 44209 | BF10: 49.98 | BG10: 50.16
C11: 44210 | D11: 80.01 | E11: 81.3 | I11: 44210 | J11: 13.57 | K11: 13.2 | O11: 44210 | P11: 9.81 | Q11: 10.17 | U11: 44210 | V11: 196.1 | W11: 197.4 | AA11: 44210 | AB11: 48.5 | AC11: 50.31 | AG11: 44210 | AH11: 140.49 | AI11: 141.17 | AM11: 44210 | AN11: 130.8 | AO11: 128.91 | AS11: 44210 | AT11: 215.91 | AU11: 213.02 | AY11: 44210 | AZ11: 49.27 | BA11: 48.99 | BE11: 44210 | BF11: 50.16 | BG11: 49.23
C12: 44211 | D12: 80.92 | E12: 80.72 | I12: 44211 | J12: 13.23 | K12: 12.86 | O12: 44211 | P12: 10.04 | Q12: 9.83 | U12: 44211 | V12: 195.66 | W12: 194.62 | AA12: 44211 | AB12: 48.91 | AC12: 47.89 | AG12: 44211 | AH12: 137.43 | AI12: 138.64 | AM12: 44211 | AN12: 128.78 | AO12: 127.14 | AS12: 44211 | AT12: 213.52 | AU12: 212.65 | AY12: 44211 | AZ12: 48.38 | BA12: 48.21 | BE12: 44211 | BF12: 49.16 | BG12: 48.7
C13: 44215 | D13: 81.28 | E13: 85.5 | I13: 44215 | J13: 13.02 | K13: 13.03 | O13: 44215 | P13: 10.06 | Q13: 10.02 | U13: 44215 | V13: 194.29 | W13: 194.06 | X13: 1.03 Dividend | AA13: 44215 | AB13: 48.45 | AC13: 48.84 | AG13: 44215 | AH13: 139.86 | AI13: 138.04 | AM13: 44215 | AN13: 127.78 | AO13: 127.83 | AS13: 44215 | AT13: 213.75 | AU13: 216.44 | AY13: 44215 | AZ13: 48.21 | BA13: 47.8 | BE13: 44215 | BF13: 48.74 | BG13: 48.51
C14: 44216 | D14: 85.93 | E14: 83.5 | I14: 44216 | J14: 13.11 | K14: 13.37 | O14: 44216 | P14: 10.23 | Q14: 10.86 | U14: 44216 | V14: 192.66 | W14: 192.34 | AA14: 44216 | AB14: 49.11 | AC14: 49.53 | AG14: 44216 | AH14: 137.82 | AI14: 135.97 | AM14: 44216 | AN14: 128.66 | AO14: 132.03 | AS14: 44216 | AT14: 217.7 | AU14: 224.34 | AY14: 44216 | AZ14: 47.86 | BA14: 48.5 | BE14: 44216 | BF14: 48.54 | BG14: 48.68
C15: 44217 | D15: 84 | E15: 85.01 | I15: 44217 | J15: 13.42 | K15: 13.87 | O15: 44217 | P15: 11.28 | Q15: 11.53 | U15: 44217 | V15: 192.35 | W15: 192.19 | AA15: 44217 | AB15: 49.33 | AC15: 48.11 | AG15: 44217 | AH15: 135.69 | AI15: 134.83 | AM15: 44217 | AN15: 133.8 | AO15: 136.87 | AS15: 44217 | AT15: 224.7 | AU15: 224.97 | AY15: 44217 | AZ15: 48.45 | BA15: 48.28 | BE15: 44217 | BF15: 48.78 | BG15: 48.95
C16: 44218 | D16: 84.08 | E16: 82.28 | I16: 44218 | J16: 13.74 | K16: 13.71 | O16: 44218 | P16: 11.66 | Q16: 11.52 | U16: 44218 | V16: 190.85 | W16: 191.94 | AA16: 44218 | AB16: 47.01 | AC16: 47.43 | AG16: 44218 | AH16: 132.69 | AI16: 133.79 | AM16: 44218 | AN16: 136.28 | AO16: 139.07 | AS16: 44218 | AT16: 227.08 | AU16: 225.95 | AY16: 44218 | AZ16: 48.53 | BA16: 48.78 | BE16: 44218 | BF16: 48.81 | BG16: 48.49
C17: 44221 | D17: 83.19 | E17: 81.28 | I17: 44221 | J17: 13.78 | K17: 13.65 | O17: 44221 | P17: 11.49 | Q17: 11.29 | U17: 44221 | V17: 190.56 | W17: 187.34 | AA17: 44221 | AB17: 46.9 | AC17: 46.9 | AG17: 44221 | AH17: 132.14 | AI17: 132.12 | AM17: 44221 | AN17: 143.07 | AO17: 142.92 | AS17: 44221 | AT17: 229.12 | AU17: 229.53 | AY17: 44221 | AZ17: 48.45 | BA17: 48.73 | BE17: 44221 | BF17: 48.42 | BG17: 48.78
C18: 44222 | D18: 81.79 | E18: 79.51 | I18: 44222 | J18: 13.58 | K18: 13.44 | O18: 44222 | P18: 11.31 | Q18: 11.19 | U18: 44222 | V18: 187.6 | W18: 187.21 | AA18: 44222 | AB18: 47.26 | AC18: 45.87 | AG18: 44222 | AH18: 132.75 | AI18: 131.58 | AM18: 44222 | AN18: 143.6 | AO18: 143.16 | AS18: 44222 | AT18: 231.86 | AU18: 232.33 | AY18: 44222 | AZ18: 48.54 | BA18: 49.17 | BE18: 44222 | BF18: 48.91 | BG18: 49.29
C19: 44223 | D19: 77.33 | E19: 75.09 | I19: 44223 | J19: 13.23 | K19: 12.92 | O19: 44223 | P19: 11.02 | Q19: 10.79 | U19: 44223 | V19: 184.2 | W19: 180.63 | AA19: 44223 | AB19: 45 | AC19: 45.35 | AG19: 44223 | AH19: 129.59 | AI19: 127.86 | AM19: 44223 | AN19: 143.43 | AO19: 142.06 | AS19: 44223 | AT19: 238 | AU19: 232.9 | AY19: 44223 | AZ19: 48.99 | BA19: 47.95 | BE19: 44223 | BF19: 48.89 | BG19: 48.53
C20: 44224 | D20: 77.2 | E20: 78.39 | I20: 44224 | J20: 13 | K20: 13.05 | O20: 44224 | P20: 10.84 | Q20: 10.72 | U20: 44224 | V20: 182.26 | W20: 184.34 | AA20: 44224 | AB20: 45.94 | AC20: 46.06 | AG20: 44224 | AH20: 129.9 | AI20: 130.11 | AM20: 44224 | AN20: 139.52 | AO20: 137.09 | AS20: 44224 | AT20: 235.61 | AU20: 238.93 | AY20: 44224 | AZ20: 48.15 | BA20: 47.92 | BE20: 44224 | BF20: 48.69 | BG20: 49.15
C21: 44225 | D21: 78.36 | E21: 78.27 | I21: 44225 | J21: 13.07 | K21: 12.99 | O21: 44225 | P21: 10.59 | Q21: 10.53 | U21: 44225 | V21: 183.5 | W21: 182.84 | AA21: 44225 | AB21: 45.55 | AC21: 44.84 | AG21: 44225 | AH21: 131.19 | AI21: 128.67 | AM21: 44225 | AN21: 135.83 | AO21: 131.96 | AS21: 44225 | AT21: 235.99 | AU21: 231.96 | AY21: 44225 | AZ21: 47.73 | BA21: 46.83 | BE21: 44225 | BF21: 49.03 | BG21: 48.15
C22: 44228 | D22: 79.59 | E22: 80.43 | I22: 44228 | J22: 13.05 | K22: 13.24 | O22: 44228 | P22: 10.65 | Q22: 10.83 | U22: 44228 | V22: 185.96 | W22: 184.72 | AA22: 44228 | AB22: 45.58 | AC22: 44.92 | AG22: 44228 | AH22: 129.4 | AI22: 129.62 | AM22: 44228 | AN22: 133.75 | AO22: 134.14 | AS22: 44228 | AT22: 235.06 | AU22: 239.65 | AY22: 44228 | AZ22: 46.97 | BA22: 46.42 | BE22: 44228 | BF22: 48.27 | BG22: 48.48
C23: 44229 | D23: 81.26 | E23: 81.62 | I23: 44229 | J23: 13.4 | K23: 13.56 | O23: 44229 | P23: 11.14 | Q23: 10.86 | U23: 44229 | V23: 186.5 | W23: 192.5 | AA23: 44229 | AB23: 45.81 | AC23: 45.63 | AG23: 44229 | AH23: 131.94 | AI23: 133.61 | AM23: 44229 | AN23: 135.73 | AO23: 134.99 | AS23: 44229 | AT23: 241.3 | AU23: 239.51 | AY23: 44229 | AZ23: 46.59 | BA23: 46.92 | BE23: 44229 | BF23: 48.8 | BG23: 48.96
C24: 44230 | D24: 81.85 | E24: 79.11 | I24: 44230 | J24: 13.64 | K24: 13.53 | O24: 44230 | P24: 10.92 | Q24: 11.2 | U24: 44230 | V24: 190.91 | W24: 191.45 | AA24: 44230 | AB24: 45.63 | AC24: 47.42 | AG24: 44230 | AH24: 133.65 | AI24: 135.14 | AM24: 44230 | AN24: 135.76 | AO24: 133.94 | AS24: 44230 | AT24: 239.57 | AU24: 243 | AY24: 44230 | AZ24: 46.89 | BA24: 47.07 | BE24: 44230 | BF24: 48.95 | BG24: 48.77
C25: 44231 | D25: 79.15 | E25: 81.25 | I25: 44231 | J25: 13.53 | K25: 13.66 | O25: 44231 | P25: 11.4 | Q25: 11.37 | U25: 44231 | V25: 192 | W25: 191.65 | AA25: 44231 | AB25: 47.88 | AC25: 48.33 | AG25: 44231 | AH25: 135.47 | AI25: 138.25 | AM25: 44231 | AN25: 136.3 | AO25: 137.39 | AS25: 44231 | AT25: 242.66 | AU25: 242.01 | AY25: 44231 | AZ25: 47.26 | BA25: 47.51 | BE25: 44231 | BF25: 48.96 | BG25: 49.01
C26: 44232 | D26: 81.77 | E26: 81.1 | I26: 44232 | J26: 13.73 | K26: 13.59 | O26: 44232 | P26: 11.8 | Q26: 11.51 | U26: 44232 | V26: 192.52 | W26: 193 | AA26: 44232 | AB26: 49.18 | AC26: 49.95 | AG26: 44232 | AH26: 139.39 | AI26: 137.98 | AM26: 44232 | AN26: 137.35 | AO26: 136.76 | AP26: 0.205 Dividend | AS26: 44232 | AT26: 242.23 | AU26: 242.2 | AY26: 44232 | AZ26: 47.82 | BA26: 48.12 | BE26: 44232 | BF26: 49.5 | BG26: 49.65
C27: 44235 | D27: 81.75 | E27: 84.01 | I27: 44235 | J27: 13.73 | K27: 14.44 | O27: 44235 | P27: 11.52 | Q27: 11.56 | U27: 44235 | V27: 195 | W27: 197.45 | AA27: 44235 | AB27: 50.92 | AC27: 52.1 | AG27: 44235 | AH27: 138.2 | AI27: 140.14 | AM27: 44235 | AN27: 136.03 | AO27: 136.91 | AS27: 44235 | AT27: 243.15 | AU27: 242.47 | AY27: 44235 | AZ27: 48.27 | BA27: 48.34 | BE27: 44235 | BF27: 49.96 | BG27: 49.92
C28: 44236 | D28: 83.35 | E28: 83.32 | I28: 44236 | J28: 14.34 | K28: 14.26 | O28: 44236 | P28: 11.54 | Q28: 11.93 | U28: 44236 | V28: 197.54 | W28: 197.28 | AA28: 44236 | AB28: 50.67 | AC28: 50.63 | AD28: 0.87 Dividend | AG28: 44236 | AH28: 139.43 | AI28: 139.58 | AM28: 44236 | AN28: 136.62 | AO28: 136.01 | AS28: 44236 | AT28: 241.87 | AU28: 243.77 | AY28: 44236 | AZ28: 48.19 | BA28: 48.61 | BE28: 44236 | BF28: 49.85 | BG28: 49.7
C29: 44237 | D29: 84 | E29: 82.35 | I29: 44237 | J29: 14.46 | K29: 14.76 | O29: 44237 | P29: 12 | Q29: 11.76 | U29: 44237 | V29: 198.5 | W29: 197.72 | AA29: 44237 | AB29: 50.63 | AC29: 51.12 | AG29: 44237 | AH29: 140 | AI29: 139.66 | AM29: 44237 | AN29: 136.48 | AO29: 135.39 | AS29: 44237 | AT29: 245 | AU29: 242.82 | AY29: 44237 | AZ29: 48.61 | BA29: 48.04 | BE29: 44237 | BF29: 50.41 | BG29: 49.6
C30: 44238 | D30: 84.4 | E30: 86.48 | I30: 44238 | J30: 14.98 | K30: 15.25 | O30: 44238 | P30: 11.66 | Q30: 11.45 | U30: 44238 | V30: 197.59 | W30: 198.35 | AA30: 44238 | AB30: 50.89 | AC30: 49.84 | AG30: 44238 | AH30: 139.66 | AI30: 139.27 | AM30: 44238 | AN30: 135.9 | AO30: 135.13 | AS30: 44238 | AT30: 244.78 | AU30: 244.49 | AY30: 44238 | AZ30: 48.05 | BA30: 48.01 | BE30: 44238 | BF30: 49.81 | BG30: 50.3
C31: 44239 | D31: 86.11 | E31: 88.01 | I31: 44239 | J31: 15.05 | K31: 14.96 | O31: 44239 | P31: 11.42 | Q31: 11.45 | U31: 44239 | V31: 197.98 | W31: 197.99 | AA31: 44239 | AB31: 49.43 | AC31: 50.52 | AG31: 44239 | AH31: 139.05 | AI31: 141.25 | AM31: 44239 | AN31: 134.35 | AO31: 135.37 | AS31: 44239 | AT31: 243.93 | AU31: 244.99 | AY31: 44239 | AZ31: 48.05 | BA31: 48.16 | BE31: 44239 | BF31: 50.57 | BG31: 50.69
C32: 44243 | D32: 89.22 | E32: 87.74 | I32: 44243 | J32: 15.06 | K32: 15.33 | O32: 44243 | P32: 11.5 | Q32: 11.54 | U32: 44243 | V32: 199.75 | W32: 202.38 | AA32: 44243 | AB32: 51.96 | AC32: 52.04 | AG32: 44243 | AH32: 143.55 | AI32: 144.65 | AM32: 44243 | AN32: 135.49 | AO32: 133.19 | AS32: 44243 | AT32: 245.03 | AU32: 243.7 | AY32: 44243 | AZ32: 48.65 | BA32: 48.55 | BE32: 44243 | BF32: 50.62 | BG32: 50.27
C33: 44244 | D33: 86.69 | E33: 86.05 | I33: 44244 | J33: 15.17 | K33: 14.91 | O33: 44244 | P33: 11.61 | Q33: 11.48 | U33: 44244 | V33: 202.39 | W33: 202.3 | AA33: 44244 | AB33: 52.35 | AC33: 52.85 | AG33: 44244 | AH33: 143.95 | AI33: 145.1 | AM33: 44244 | AN33: 131.25 | AO33: 130.84 | AS33: 44244 | AT33: 241.32 | AU33: 244.2 | AV33: 0.56 Dividend | AY33: 44244 | AZ33: 48.22 | BA33: 49.07 | BE33: 44244 | BF33: 50 | BG33: 50.13
C34: 44245 | D34: 86.52 | E34: 88.54 | I34: 44245 | J34: 14.73 | K34: 14.83 | O34: 44245 | P34: 11.37 | Q34: 11.43 | U34: 44245 | V34: 201.55 | W34: 199.92 | AA34: 44245 | AB34: 52.81 | AC34: 52.02 | AG34: 44245 | AH34: 144 | AI34: 145.59 | AM34: 44245 | AN34: 129.2 | AO34: 129.71 | AS34: 44245 | AT34: 241.8 | AU34: 243.79 | AY34: 44245 | AZ34: 46.33 | BA34: 45.89 | BE34: 44245 | BF34: 50.16 | BG34: 50.77
C35: 44246 | D35: 90.25 | E35: 90.96 | I35: 44246 | J35: 15.02 | K35: 14.93 | O35: 44246 | P35: 11.52 | Q35: 11.58 | U35: 44246 | V35: 203.25 | W35: 209.91 | AA35: 44246 | AB35: 52.11 | AC35: 52.37 | AG35: 44246 | AH35: 145.86 | AI35: 148.02 | AM35: 44246 | AN35: 130.24 | AO35: 129.87 | AS35: 44246 | AT35: 243.75 | AU35: 240.97 | AY35: 44246 | AZ35: 45.93 | BA35: 46.11 | BE35: 44246 | BF35: 50.79 | BG35: 50.11
C36: 44249 | D36: 89.53 | E36: 86.28 | I36: 44249 | J36: 14.77 | K36: 14.36 | O36: 44249 | P36: 11.52 | Q36: 11.7 | U36: 44249 | V36: 209.63 | W36: 218.06 | AA36: 44249 | AB36: 52.59 | AC36: 54.3 | AG36: 44249 | AH36: 146.87 | AI36: 149.41 | AM36: 44249 | AN36: 128.01 | AO36: 126 | AS36: 44249 | AT36: 237.42 | AU36: 234.51 | AY36: 44249 | AZ36: 45.91 | BA36: 45.9 | BE36: 44249 | BF36: 49.85 | BG36: 50.63
C37: 44250 | D37: 85.24 | E37: 88.23 | I37: 44250 | J37: 14.08 | K37: 14.14 | O37: 44250 | P37: 11.59 | Q37: 11.62 | U37: 44250 | V37: 219.53 | W37: 220.18 | AA37: 44250 | AB37: 54.98 | AC37: 55.05 | AG37: 44250 | AH37: 151.51 | AI37: 150.61 | AM37: 44250 | AN37: 123.76 | AO37: 125.86 | AS37: 44250 | AT37: 230.33 | AU37: 233.27 | AY37: 44250 | AZ37: 45.7 | BA37: 45.16 | BE37: 44250 | BF37: 51 | BG37: 50.54
C38: 44251 | D38: 88.3 | E38: 92.52 | I38: 44251 | J38: 14.12 | K38: 14.5 | O38: 44251 | P38: 11.67 | Q38: 12.27 | U38: 44251 | V38: 220.41 | W38: 222.47 | AA38: 44251 | AB38: 55.19 | AC38: 56.7 | AG38: 44251 | AH38: 150.11 | AI38: 153.26 | AM38: 44251 | AN38: 124.94 | AO38: 125.35 | AS38: 44251 | AT38: 230.01 | AU38: 234.55 | AY38: 44251 | AZ38: 45.29 | BA38: 44.4 | BE38: 44251 | BF38: 50.39 | BG38: 50.71
C39: 44252 | D39: 91.52 | E39: 88.12 | I39: 44252 | J39: 14.05 | K39: 13.31 | O39: 44252 | P39: 12.22 | Q39: 11.76 | U39: 44252 | V39: 223.62 | W39: 221.82 | AA39: 44252 | AB39: 56.98 | AC39: 55.76 | AG39: 44252 | AH39: 154.27 | AI39: 151.18 | AM39: 44252 | AN39: 124.68 | AO39: 120.99 | AS39: 44252 | AT39: 232.08 | AU39: 228.99 | AY39: 44252 | AZ39: 44.37 | BA39: 43.98 | BE39: 44252 | BF39: 50.47 | BG39: 50.17
C40: 44253 | D40: 89.74 | E40: 91.53 | I40: 44253 | J40: 13.75 | K40: 13.71 | O40: 44253 | P40: 11.89 | Q40: 11.7 | U40: 44253 | V40: 220.75 | W40: 215.88 | AA40: 44253 | AB40: 54.41 | AC40: 54.37 | AG40: 44253 | AH40: 150.3 | AI40: 147.17 | AM40: 44253 | AN40: 122.59 | AO40: 121.26 | AS40: 44253 | AT40: 231.53 | AU40: 232.38 | AY40: 44253 | AZ40: 43.83 | BA40: 43.31 | BE40: 44253 | BF40: 50.2 | BG40: 48.99
...

Sheet Calculations
B2: Ticker | C2: Date | D2: Open | E2: Close | F2: Daily Return | G2: Overnight Return | H2: Daytime Return | I2: Night-day Difference | K2: Ticker | L2: Date | M2: Open | N2: Close | O2: Daily Return | P2: Overnight Return | Q2: Daytime Return | R2: Night-day Difference | T2: Ticker | U2: Date | V2: Open | W2: Close | X2: Daily Return | Y2: Overnight Return | Z2: Daytime Return | AA2: Night-day Difference | AC2: Ticker | AD2: Date | AE2: Open | AF2: Close | AG2: Daily Return | AH2: Overnight Return | AI2: Daytime Return | AJ2: Night-day Difference | AL2: Ticker | AM2: Date | AN2: Open | AO2: Close | AP2: Daily Return | AQ2: Overnight Return | AR2: Daytime Return | AS2: Night-day Difference | AU2: Ticker | AV2: Date | AW2: Open | AX2: Close | AY2: Daily Return | AZ2: Overnight Return | BA2: Daytime Return | BB2: Night-day Difference | BD2: Ticker | BE2: Date | BF2: Open | BG2: Close | BH2: Daily Return | BI2: Overnight Return | BJ2: Daytime Return | BK2: Night-day Difference | BM2: Ticker | BN2: Date | BO2: Open | BP2: Close | BQ2: Daily Return | BR2: Overnight Return | BS2: Daytime Return | BT2: Night-day Difference | BV2: Ticker | BW2: Date | BX2: Open | BY2: Close | BZ2: Daily Return | CA2: Overnight Return | CB2: Daytime Return | CC2: Night-day Difference | CE2: Ticker | CF2: Date | CG2: Open | CH2: Close | CI2: Daily Return | CJ2: Overnight Return | CK2: Daytime Return | CL2: Night-day Difference
B3: MU | C3: 44200 | D3: 76.48 | E3: 74.05 | F3: reference | G3: reference | H3: =E3/D3-1 -> -0.031773013 | I3: reference | K3: NVDA | L3: 44200 | M3: 13.1 | N3: 13.11 | O3: reference | P3: reference | Q3: =N3/M3-1 -> 0.00076335878 | R3: reference | T3: F | U3: 44200 | V3: 8.81 | W3: 8.52 | X3: reference | Y3: reference | Z3: =W3/V3-1 -> -0.03291714 | AA3: reference | AC3: CAT | AD3: 44200 | AE3: 183 | AF3: 182.15 | AG3: reference | AH3: reference | AI3: =AF3/AE3-1 -> -0.0046448087 | AJ3: reference | AL3: XOM | AM3: 44200 | AN3: 41.45 | AO3: 41.5 | AP3: reference | AQ3: reference | AR3: =AO3/AN3-1 -> 0.0012062726 | AS3: reference | AU3: JPM | AV3: 44200 | AW3: 127.5 | AX3: 125.87 | AY3: reference | AZ3: reference | BA3: =AX3/AW3-1 -> -0.012784314 | BB3: reference | BD3: AAPL | BE3: 44200 | BF3: 133.52 | BG3: 129.41 | BH3: reference | BI3: reference | BJ3: =BG3/BF3-1 -> -0.030781905 | BK3: reference | BM3: MSFT | BN3: 44200 | BO3: 222.53 | BP3: 217.69 | BQ3: reference | BR3: reference | BS3: =BP3/BO3-1 -> -0.021749876 | BT3: reference | BV3: WMT | BW3: 44200 | BX3: 48.1 | BY3: 48.84 | BZ3: reference | CA3: reference | CB3: =BY3/BX3-1 -> 0.015384615 | CC3: reference | CE3: KO | CF3: 44200 | CG3: 54.27 | CH3: 52.76 | CI3: reference | CJ3: reference | CK3: =CH3/CG3-1 -> -0.027823844 | CL3: reference
C4: 44201 | D4: 76.44 | E4: 77.26 | F4: =E4/E3-1 -> 0.043349088 | G4: =D4/E3-1 -> 0.03227549 | H4: =E4/D4-1 -> 0.010727368 | I4: =G4-H4 -> 0.021548122 | L4: 44201 | M4: 13.1 | N4: 13.4 | O4: =N4/N3-1 -> 0.022120519 | P4: =M4/N3-1 -> -0.00076277651 | Q4: =N4/M4-1 -> 0.022900763 | R4: =P4-Q4 -> -0.02366354 | U4: 44201 | V4: 8.47 | W4: 8.65 | X4: =W4/W3-1 -> 0.015258216 | Y4: =V4/W3-1 -> -0.0058685446 | Z4: =W4/V4-1 -> 0.021251476 | AA4: =Y4-Z4 -> -0.02712002 | AD4: 44201 | AE4: 181.21 | AF4: 183.64 | AG4: =AF4/AF3-1 -> 0.0081800714 | AH4: =AE4/AF3-1 -> -0.0051605819 | AI4: =AF4/AE4-1 -> 0.013409856 | AJ4: =AH4-AI4 -> -0.018570438 | AM4: 44201 | AN4: 41.84 | AO4: 43.5 | AP4: =AO4/AO3-1 -> 0.048192771 | AQ4: =AN4/AO3-1 -> 0.0081927711 | AR4: =AO4/AN4-1 -> 0.039674952 | AS4: =AQ4-AR4 -> -0.031482181 | AV4: 44201 | AW4: 124.99 | AX4: 125.65 | AY4: =AX4/AX3-1 -> -0.0017478351 | AZ4: =AW4/AX3-1 -> -0.0069913403 | BA4: =AX4/AW4-1 -> 0.0052804224 | BB4: =AZ4-BA4 -> -0.012271763 | BE4: 44201 | BF4: 128.89 | BG4: 131.01 | BH4: =BG4/BG3-1 -> 0.012363805 | BI4: =BF4/BG3-1 -> -0.0040182366 | BJ4: =BG4/BF4-1 -> 0.016448134 | BK4: =BI4-BJ4 -> -0.020466371 | BN4: 44201 | BO4: 217.26 | BP4: 217.9 | BQ4: =BP4/BP3-1 -> 0.00096467454 | BR4: =BO4/BP3-1 -> -0.001975286 | BS4: =BP4/BO4-1 -> 0.0029457793 | BT4: =BR4-BS4 -> -0.0049210652 | BW4: 44201 | BX4: 48.87 | BY4: 48.58 | BZ4: =BY4/BY3-1 -> -0.0053235053 | CA4: =BX4/BY3-1 -> 0.00061425061 | CB4: =BY4/BX4-1 -> -0.0059341109 | CC4: =CA4-CB4 -> 0.0065483615 | CF4: 44201 | CG4: 52.33 | CH4: 52.18 | CI4: =CH4/CH3-1 -> -0.010993177 | CJ4: =CG4/CH3-1 -> -0.0081501137 | CK4: =CH4/CG4-1 -> -0.0028664246 | CL4: =CJ4-CK4 -> -0.0052836891
C5: 44202 | D5: 76.36 | E5: 77.11 | F5: =E5/E4-1 -> -0.0019414962 | G5: =D5/E4-1 -> -0.011648977 | H5: =E5/D5-1 -> 0.0098218963 | I5: =G5-H5 -> -0.021470874 | L5: 44202 | M5: 13.22 | N5: 12.61 | O5: =N5/N4-1 -> -0.058955224 | P5: =M5/N4-1 -> -0.013432836 | Q5: =N5/M5-1 -> -0.046142209 | R5: =P5-Q5 -> 0.032709373 | U5: 44202 | V5: 8.79 | W5: 8.84 | X5: =W5/W4-1 -> 0.021965318 | Y5: =V5/W4-1 -> 0.016184971 | Z5: =W5/V5-1 -> 0.0056882821 | AA5: =Y5-Z5 -> 0.010496689 | AD5: 44202 | AE5: 187.15 | AF5: 193.86 | AG5: =AF5/AF4-1 -> 0.055652363 | AH5: =AE5/AF4-1 -> 0.019113483 | AI5: =AF5/AE5-1 -> 0.035853593 | AJ5: =AH5-AI5 -> -0.01674011 | AM5: 44202 | AN5: 44.41 | AO5: 44.61 | AP5: =AO5/AO4-1 -> 0.025517241 | AQ5: =AN5/AO4-1 -> 0.02091954 | AR5: =AO5/AN5-1 -> 0.0045034902 | AS5: =AQ5-AR5 -> 0.01641605 | AV5: 44202 | AW5: 129.88 | AX5: 131.55 | AY5: =AX5/AX4-1 -> 0.04695583 | AZ5: =AW5/AX4-1 -> 0.033664942 | BA5: =AX5/AW5-1 -> 0.012858023 | BB5: =AZ5-BA5 -> 0.02080692 | BE5: 44202 | BF5: 127.72 | BG5: 126.6 | BH5: =BG5/BG4-1 -> -0.033661553 | BI5: =BF5/BG4-1 -> -0.025112587 | BJ5: =BG5/BF5-1 -> -0.0087691826 | BK5: =BI5-BJ5 -> -0.016343404 | BN5: 44202 | BO5: 212.17 | BP5: 212.25 | BQ5: =BP5/BP4-1 -> -0.025929325 | BR5: =BO5/BP4-1 -> -0.026296466 | BS5: =BP5/BO5-1 -> 0.00037705613 | BT5: =BR5-BS5 -> -0.026673522 | BW5: 44202 | BX5: 48.36 | BY5: 48.89 | BZ5: =BY5/BY4-1 -> 0.0063812268 | CA5: =BX5/BY4-1 -> -0.0045286126 | CB5: =BY5/BX5-1 -> 0.010959471 | CC5: =CA5-CB5 -> -0.015488083 | CF5: 44202 | CG5: 51.97 | CH5: 50.52 | CI5: =CH5/CH4-1 -> -0.031812955 | CJ5: =CG5/CH4-1 -> -0.0040245305 | CK5: =CH5/CG5-1 -> -0.027900712 | CL5: =CJ5-CK5 -> 0.023876181
C6: 44203 | D6: 78.06 | E6: 79.11 | F6: =E6/E5-1 -> 0.025936973 | G6: =D6/E5-1 -> 0.012320062 | H6: =E6/D6-1 -> 0.013451191 | I6: =G6-H6 -> -0.0011311291 | L6: 44203 | M6: 12.97 | N6: 13.34 | O6: =N6/N5-1 -> 0.057890563 | P6: =M6/N5-1 -> 0.028548771 | Q6: =N6/M6-1 -> 0.028527371 | R6: =P6-Q6 -> 2.1399961e-05 | U6: 44203 | V6: 8.94 | W6: 9.06 | X6: =W6/W5-1 -> 0.024886878 | Y6: =V6/W5-1 -> 0.011312217 | Z6: =W6/V6-1 -> 0.013422819 | AA6: =Y6-Z6 -> -0.0021106016 | AD6: 44203 | AE6: 196.85 | AF6: 194.23 | AG6: =AF6/AF5-1 -> 0.0019085938 | AH6: =AE6/AF5-1 -> 0.015423501 | AI6: =AF6/AE6-1 -> -0.013309627 | AJ6: =AH6-AI6 -> 0.028733128 | AM6: 44203 | AN6: 45 | AO6: 44.96 | AP6: =AO6/AO5-1 -> 0.0078457745 | AQ6: =AN6/AO5-1 -> 0.0087424344 | AR6: =AO6/AN6-1 -> -0.00088888889 | AS6: =AQ6-AR6 -> 0.0096313233 | AV6: 44203 | AW6: 135.69 | AX6: 135.87 | AY6: =AX6/AX5-1 -> 0.032839225 | AZ6: =AW6/AX5-1 -> 0.031470924 | BA6: =AX6/AW6-1 -> 0.0013265532 | BB6: =AZ6-BA6 -> 0.03014437 | BE6: 44203 | BF6: 128.36 | BG6: 130.92 | BH6: =BG6/BG5-1 -> 0.034123223 | BI6: =BF6/BG5-1 -> 0.013902054 | BJ6: =BG6/BF6-1 -> 0.019943908 | BK6: =BI6-BJ6 -> -0.006041854 | BN6: 44203 | BO6: 214.04 | BP6: 218.29 | BQ6: =BP6/BP5-1 -> 0.028457008 | BR6: =BO6/BP5-1 -> 0.0084334511 | BS6: =BP6/BO6-1 -> 0.019856102 | BT6: =BR6-BS6 -> -0.011422651 | BW6: 44203 | BX6: 49.21 | BY6: 48.88 | BZ6: =BY6/BY5-1 -> -0.00020454081 | CA6: =BX6/BY5-1 -> 0.0065453058 | CB6: =BY6/BX6-1 -> -0.0067059541 | CC6: =CA6-CB6 -> 0.01325126 | CF6: 44203 | CG6: 50.09 | CH6: 49.96 | CI6: =CH6/CH5-1 -> -0.011084719 | CJ6: =CG6/CH5-1 -> -0.0085114806 | CK6: =CH6/CG6-1 -> -0.0025953284 | CL6: =CJ6-CK6 -> -0.0059161522
C7: 44204 | D7: 82.54 | E7: 77.42 | F7: =E7/E6-1 -> -0.02136266 | G7: =D7/E6-1 -> 0.043357351 | H7: =E7/D7-1 -> -0.062030531 | I7: =G7-H7 -> 0.10538788 | L7: 44204 | M7: 13.36 | N7: 13.28 | O7: =N7/N6-1 -> -0.0044977511 | P7: =M7/N6-1 -> 0.0014992504 | Q7: =N7/M7-1 -> -0.005988024 | R7: =P7-Q7 -> 0.0074872743 | U7: 44204 | V7: 9.1 | W7: 9 | X7: =W7/W6-1 -> -0.0066225166 | Y7: =V7/W6-1 -> 0.004415011 | Z7: =W7/V7-1 -> -0.010989011 | AA7: =Y7-Z7 -> 0.015404022 | AD7: 44204 | AE7: 193.85 | AF7: 194.26 | AG7: =AF7/AF6-1 -> 0.00015445606 | AH7: =AE7/AF6-1 -> -0.0019564434 | AI7: =AF7/AE7-1 -> 0.0021150374 | AJ7: =AH7-AI7 -> -0.0040714808 | AM7: 44204 | AN7: 45.2 | AO7: 45.46 | AP7: =AO7/AO6-1 -> 0.011120996 | AQ7: =AN7/AO6-1 -> 0.0053380783 | AR7: =AO7/AN7-1 -> 0.0057522124 | AS7: =AQ7-AR7 -> -0.0004141341 | AV7: 44204 | AW7: 135.97 | AX7: 136.02 | AY7: =AX7/AX6-1 -> 0.0011039965 | AZ7: =AW7/AX6-1 -> 0.00073599764 | BA7: =AX7/AW7-1 -> 0.00036772818 | BB7: =AZ7-BA7 -> 0.00036826947 | BE7: 44204 | BF7: 132.43 | BG7: 132.05 | BH7: =BG7/BG6-1 -> 0.0086312252 | BI7: =BF7/BG6-1 -> 0.011533761 | BJ7: =BG7/BF7-1 -> -0.0028694405 | BK7: =BI7-BJ7 -> 0.014403202 | BN7: 44204 | BO7: 218.68 | BP7: 219.62 | BQ7: =BP7/BP6-1 -> 0.0060928123 | BR7: =BO7/BP6-1 -> 0.0017866141 | BS7: =BP7/BO7-1 -> 0.0042985184 | BT7: =BR7-BS7 -> -0.0025119042 | BW7: 44204 | BX7: 48.96 | BY7: 48.88 | BZ7: =BY7/BY6-1 -> 0 | CA7: =BX7/BY6-1 -> 0.0016366612 | CB7: =BY7/BX7-1 -> -0.0016339869 | CC7: =CA7-CB7 -> 0.0032706481 | CF7: 44204 | CG7: 50.03 | CH7: 51.08 | CI7: =CH7/CH6-1 -> 0.022417934 | CJ7: =CG7/CH6-1 -> 0.0014011209 | CK7: =CH7/CG7-1 -> 0.020987408 | CL7: =CJ7-CK7 -> -0.019586287
C8: 44207 | D8: 76.59 | E8: 78.67 | F8: =E8/E7-1 -> 0.016145699 | G8: =D8/E7-1 -> -0.010720744 | H8: =E8/D8-1 -> 0.027157592 | I8: =G8-H8 -> -0.037878336 | L8: 44207 | M8: 13.42 | N8: 13.62 | O8: =N8/N7-1 -> 0.02560241 | P8: =M8/N7-1 -> 0.010542169 | Q8: =N8/M8-1 -> 0.01490313 | R8: =P8-Q8 -> -0.004360961 | U8: 44207 | V8: 8.87 | W8: 9.3 | X8: =W8/W7-1 -> 0.033333333 | Y8: =V8/W7-1 -> -0.014444444 | Z8: =W8/V8-1 -> 0.048478016 | AA8: =Y8-Z8 -> -0.06292246 | AD8: 44207 | AE8: 191.56 | AF8: 193.86 | AG8: =AF8/AF7-1 -> -0.0020590961 | AH8: =AE8/AF7-1 -> -0.013898898 | AI8: =AF8/AE8-1 -> 0.012006682 | AJ8: =AH8-AI8 -> -0.02590558 | AM8: 44207 | AN8: 45.04 | AO8: 46.84 | AP8: =AO8/AO7-1 -> 0.030356357 | AQ8: =AN8/AO7-1 -> -0.0092388913 | AR8: =AO8/AN8-1 -> 0.039964476 | AS8: =AQ8-AR8 -> -0.049203367 | AV8: 44207 | AW8: 134.58 | AX8: 138.05 | AY8: =AX8/AX7-1 -> 0.014924276 | AZ8: =AW8/AX7-1 -> -0.010586678 | BA8: =AX8/AW8-1 -> 0.02578392 | BB8: =AZ8-BA8 -> -0.036370599 | BE8: 44207 | BF8: 129.19 | BG8: 128.98 | BH8: =BG8/BG7-1 -> -0.023248769 | BI8: =BF8/BG7-1 -> -0.021658463 | BJ8: =BG8/BF8-1 -> -0.0016255128 | BK8: =BI8-BJ8 -> -0.02003295 | BN8: 44207 | BO8: 218.47 | BP8: 217.49 | BQ8: =BP8/BP7-1 -> -0.0096985703 | BR8: =BO8/BP7-1 -> -0.0052363173 | BS8: =BP8/BO8-1 -> -0.0044857417 | BT8: =BR8-BS8 -> -0.00075057553 | BW8: 44207 | BX8: 48.67 | BY8: 49.1 | BZ8: =BY8/BY7-1 -> 0.0045008183 | CA8: =BX8/BY7-1 -> -0.0042962357 | CB8: =BY8/BX8-1 -> 0.0088350113 | CC8: =CA8-CB8 -> -0.013131247 | CF8: 44207 | CG8: 50.62 | CH8: 50.2 | CI8: =CH8/CH7-1 -> -0.017227878 | CJ8: =CG8/CH7-1 -> -0.0090054816 | CK8: =CH8/CG8-1 -> -0.0082971158 | CL8: =CJ8-CK8 -> -0.00070836583
C9: 44208 | D9: 79.19 | E9: 79.46 | F9: =E9/E8-1 -> 0.010041947 | G9: =D9/E8-1 -> 0.0066098894 | H9: =E9/D9-1 -> 0.0034095214 | I9: =G9-H9 -> 0.003200368 | L9: 44208 | M9: 13.75 | N9: 13.48 | O9: =N9/N8-1 -> -0.010279001 | P9: =M9/N8-1 -> 0.0095447871 | Q9: =N9/M9-1 -> -0.019636364 | R9: =P9-Q9 -> 0.029181151 | U9: 44208 | V9: 9.3 | W9: 9.78 | X9: =W9/W8-1 -> 0.051612903 | Y9: =V9/W8-1 -> 0 | Z9: =W9/V9-1 -> 0.051612903 | AA9: =Y9-Z9 -> -0.051612903 | AD9: 44208 | AE9: 194.68 | AF9: 197.54 | AG9: =AF9/AF8-1 -> 0.018982771 | AH9: =AE9/AF8-1 -> 0.0042298566 | AI9: =AF9/AE9-1 -> 0.014690775 | AJ9: =AH9-AI9 -> -0.010460918 | AM9: 44208 | AN9: 47.46 | AO9: 47.88 | AP9: =AO9/AO8-1 -> 0.022203245 | AQ9: =AN9/AO8-1 -> 0.01323655 | AR9: =AO9/AN9-1 -> 0.0088495575 | AS9: =AQ9-AR9 -> 0.0043869924 | AV9: 44208 | AW9: 139.44 | AX9: 140.22 | AY9: =AX9/AX8-1 -> 0.015718942 | AZ9: =AW9/AX8-1 -> 0.010068816 | BA9: =AX9/AW9-1 -> 0.0055938038 | BB9: =AZ9-BA9 -> 0.0044750119 | BE9: 44208 | BF9: 128.5 | BG9: 128.8 | BH9: =BG9/BG8-1 -> -0.0013955652 | BI9: =BF9/BG8-1 -> -0.0037215072 | BJ9: =BG9/BF9-1 -> 0.0023346304 | BK9: =BI9-BJ9 -> -0.0060561376 | BN9: 44208 | BO9: 216.5 | BP9: 214.93 | BQ9: =BP9/BP8-1 -> -0.011770656 | BR9: =BO9/BP8-1 -> -0.0045519334 | BS9: =BP9/BO9-1 -> -0.0072517321 | BT9: =BR9-BS9 -> 0.0026997987 | BW9: 44208 | BX9: 49.67 | BY9: 49.66 | BZ9: =BY9/BY8-1 -> 0.011405295 | CA9: =BX9/BY8-1 -> 0.011608961 | CB9: =BY9/BX9-1 -> -0.00020132877 | CC9: =CA9-CB9 -> 0.01181029 | CF9: 44208 | CG9: 50.04 | CH9: 50.11 | CI9: =CH9/CH8-1 -> -0.0017928287 | CJ9: =CG9/CH8-1 -> -0.003187251 | CK9: =CH9/CG9-1 -> 0.0013988809 | CL9: =CJ9-CK9 -> -0.0045861319
C10: 44209 | D10: 78.95 | E10: 79.91 | F10: =E10/E9-1 -> 0.0056632268 | G10: =D10/E9-1 -> -0.0064183237 | H10: =E10/D10-1 -> 0.012159595 | I10: =G10-H10 -> -0.018577918 | L10: 44209 | M10: 13.49 | N10: 13.53 | O10: =N10/N9-1 -> 0.0037091988 | P10: =M10/N9-1 -> 0.00074183976 | Q10: =N10/M10-1 -> 0.0029651594 | R10: =P10-Q10 -> -0.0022233196 | U10: 44209 | V10: 9.91 | W10: 9.78 | X10: =W10/W9-1 -> 0 | Y10: =V10/W9-1 -> 0.013292434 | Z10: =W10/V10-1 -> -0.013118063 | AA10: =Y10-Z10 -> 0.026410496 | AD10: 44209 | AE10: 198.79 | AF10: 195.89 | AG10: =AF10/AF9-1 -> -0.0083527387 | AH10: =AE10/AF9-1 -> 0.0063278323 | AI10: =AF10/AE10-1 -> -0.014588259 | AJ10: =AH10-AI10 -> 0.020916091 | AM10: 44209 | AN10: 48.53 | AO10: 48.42 | AP10: =AO10/AO9-1 -> 0.011278195 | AQ10: =AN10/AO9-1 -> 0.013575606 | AR10: =AO10/AN10-1 -> -0.0022666392 | AS10: =AQ10-AR10 -> 0.015842245 | AV10: 44209 | AW10: 138.59 | AX10: 140.35 | AY10: =AX10/AX9-1 -> 0.00092711453 | AZ10: =AW10/AX9-1 -> -0.01162459 | BA10: =AX10/AW10-1 -> 0.012699329 | BB10: =AZ10-BA10 -> -0.024323919 | BE10: 44209 | BF10: 128.76 | BG10: 130.89 | BH10: =BG10/BG9-1 -> 0.016226708 | BI10: =BF10/BG9-1 -> -0.00031055901 | BJ10: =BG10/BF10-1 -> 0.016542404 | BK10: =BI10-BJ10 -> -0.016852963 | BN10: 44209 | BO10: 214.02 | BP10: 216.34 | BQ10: =BP10/BP9-1 -> 0.0065602754 | BR10: =BO10/BP9-1 -> -0.0042339366 | BS10: =BP10/BO10-1 -> 0.010840108 | BT10: =BR10-BS10 -> -0.015074045 | BW10: 44209 | BX10: 49.58 | BY10: 49.15 | BZ10: =BY10/BY9-1 -> -0.010269835 | CA10: =BX10/BY9-1 -> -0.0016109545 | CB10: =BY10/BX10-1 -> -0.008672852 | CC10: =CA10-CB10 -> 0.0070618975 | CF10: 44209 | CG10: 49.98 | CH10: 50.16 | CI10: =CH10/CH9-1 -> 0.00099780483 | CJ10: =CG10/CH9-1 -> -0.0025942926 | CK10: =CH10/CG10-1 -> 0.0036014406 | CL10: =CJ10-CK10 -> -0.0061957331
C11: 44210 | D11: 80.01 | E11: 81.3 | F11: =E11/E10-1 -> 0.017394569 | G11: =D11/E10-1 -> 0.0012514078 | H11: =E11/D11-1 -> 0.016122985 | I11: =G11-H11 -> -0.014871577 | L11: 44210 | M11: 13.57 | N11: 13.2 | O11: =N11/N10-1 -> -0.024390244 | P11: =M11/N10-1 -> 0.0029563932 | Q11: =N11/M11-1 -> -0.027266028 | R11: =P11-Q11 -> 0.030222421 | U11: 44210 | V11: 9.81 | W11: 10.17 | X11: =W11/W10-1 -> 0.039877301 | Y11: =V11/W10-1 -> 0.0030674847 | Z11: =W11/V11-1 -> 0.036697248 | AA11: =Y11-Z11 -> -0.033629763 | AD11: 44210 | AE11: 196.1 | AF11: 197.4 | AG11: =AF11/AF10-1 -> 0.0077084078 | AH11: =AE11/AF10-1 -> 0.0010720302 | AI11: =AF11/AE11-1 -> 0.0066292708 | AJ11: =AH11-AI11 -> -0.0055572406 | AM11: 44210 | AN11: 48.5 | AO11: 50.31 | AP11: =AO11/AO10-1 -> 0.039033457 | AQ11: =AN11/AO10-1 -> 0.0016522098 | AR11: =AO11/AN11-1 -> 0.037319588 | AS11: =AQ11-AR11 -> -0.035667378 | AV11: 44210 | AW11: 140.49 | AX11: 141.17 | AY11: =AX11/AX10-1 -> 0.0058425365 | AZ11: =AW11/AX10-1 -> 0.00099750623 | BA11: =AX11/AW11-1 -> 0.0048402021 | BB11: =AZ11-BA11 -> -0.0038426959 | BE11: 44210 | BF11: 130.8 | BG11: 128.91 | BH11: =BG11/BG10-1 -> -0.015127206 | BI11: =BF11/BG10-1 -> -0.00068760028 | BJ11: =BG11/BF11-1 -> -0.014449541 | BK11: =BI11-BJ11 -> 0.013761941 | BN11: 44210 | BO11: 215.91 | BP11: 213.02 | BQ11: =BP11/BP10-1 -> -0.015346214 | BR11: =BO11/BP10-1 -> -0.0019876121 | BS11: =BP11/BO11-1 -> -0.013385207 | BT11: =BR11-BS11 -> 0.011397595 | BW11: 44210 | BX11: 49.27 | BY11: 48.99 | BZ11: =BY11/BY10-1 -> -0.0032553408 | CA11: =BX11/BY10-1 -> 0.0024415056 | CB11: =BY11/BX11-1 -> -0.0056829714 | CC11: =CA11-CB11 -> 0.008124477 | CF11: 44210 | CG11: 50.16 | CH11: 49.23 | CI11: =CH11/CH10-1 -> -0.01854067 | CJ11: =CG11/CH10-1 -> 0 | CK11: =CH11/CG11-1 -> -0.01854067 | CL11: =CJ11-CK11 -> 0.01854067
C12: 44211 | D12: 80.92 | E12: 80.72 | F12: =E12/E11-1 -> -0.0071340713 | G12: =D12/E11-1 -> -0.0046740467 | H12: =E12/D12-1 -> -0.0024715769 | I12: =G12-H12 -> -0.0022024699 | L12: 44211 | M12: 13.23 | N12: 12.86 | O12: =N12/N11-1 -> -0.025757576 | P12: =M12/N11-1 -> 0.0022727273 | Q12: =N12/M12-1 -> -0.027966742 | R12: =P12-Q12 -> 0.03023947 | U12: 44211 | V12: 10.04 | W12: 9.83 | X12: =W12/W11-1 -> -0.033431662 | Y12: =V12/W11-1 -> -0.012782694 | Z12: =W12/V12-1 -> -0.020916335 | AA12: =Y12-Z12 -> 0.0081336405 | AD12: 44211 | AE12: 195.66 | AF12: 194.62 | AG12: =AF12/AF11-1 -> -0.01408308 | AH12: =AE12/AF11-1 -> -0.0088145897 | AI12: =AF12/AE12-1 -> -0.0053153429 | AJ12: =AH12-AI12 -> -0.0034992467 | AM12: 44211 | AN12: 48.91 | AO12: 47.89 | AP12: =AO12/AO11-1 -> -0.048101769 | AQ12: =AN12/AO11-1 -> -0.02782747 | AR12: =AO12/AN12-1 -> -0.020854631 | AS12: =AQ12-AR12 -> -0.0069728387 | AV12: 44211 | AW12: 137.43 | AX12: 138.64 | AY12: =AX12/AX11-1 -> -0.017921655 | AZ12: =AW12/AX11-1 -> -0.026492881 | BA12: =AX12/AW12-1 -> 0.0088044823 | BB12: =AZ12-BA12 -> -0.035297363 | BE12: 44211 | BF12: 128.78 | BG12: 127.14 | BH12: =BG12/BG11-1 -> -0.01373051 | BI12: =BF12/BG11-1 -> -0.0010084555 | BJ12: =BG12/BF12-1 -> -0.012734897 | BK12: =BI12-BJ12 -> 0.011726441 | BN12: 44211 | BO12: 213.52 | BP12: 212.65 | BQ12: =BP12/BP11-1 -> -0.0017369261 | BR12: =BO12/BP11-1 -> 0.0023471974 | BS12: =BP12/BO12-1 -> -0.0040745598 | BT12: =BR12-BS12 -> 0.0064217572 | BW12: 44211 | BX12: 48.38 | BY12: 48.21 | BZ12: =BY12/BY11-1 -> -0.015921617 | CA12: =BX12/BY11-1 -> -0.012451521 | CB12: =BY12/BX12-1 -> -0.0035138487 | CC12: =CA12-CB12 -> -0.008937672 | CF12: 44211 | CG12: 49.16 | CH12: 48.7 | CI12: =CH12/CH11-1 -> -0.010765793 | CJ12: =CG12/CH11-1 -> -0.0014218972 | CK12: =CH12/CG12-1 -> -0.009357201 | CL12: =CJ12-CK12 -> 0.0079353038
C13: 44215 | D13: 81.28 | E13: 85.5 | F13: =E13/E12-1 -> 0.059217047 | G13: =D13/E12-1 -> 0.0069375619 | H13: =E13/D13-1 -> 0.051919291 | I13: =G13-H13 -> -0.044981729 | L13: 44215 | M13: 13.02 | N13: 13.03 | O13: =N13/N12-1 -> 0.013219285 | P13: =M13/N12-1 -> 0.01244168 | Q13: =N13/M13-1 -> 0.00076804916 | R13: =P13-Q13 -> 0.01167363 | U13: 44215 | V13: 10.06 | W13: 10.02 | X13: =W13/W12-1 -> 0.019328586 | Y13: =V13/W12-1 -> 0.023397762 | Z13: =W13/V13-1 -> -0.0039761431 | AA13: =Y13-Z13 -> 0.027373905 | AD13: 44215 | AE13: 194.29 | AF13: 194.06 | AG13: =AF13/AF12-1 -> -0.0028774021 | AH13: =AE13/AF12-1 -> -0.001695612 | AI13: =AF13/AE13-1 -> -0.0011837974 | AJ13: =AH13-AI13 -> -0.00051181455 | AM13: 44215 | AN13: 48.45 | AO13: 48.84 | AP13: =AO13/AO12-1 -> 0.019837127 | AQ13: =AN13/AO12-1 -> 0.011693464 | AR13: =AO13/AN13-1 -> 0.0080495356 | AS13: =AQ13-AR13 -> 0.0036439286 | AV13: 44215 | AW13: 139.86 | AX13: 138.04 | AY13: =AX13/AX12-1 -> -0.0043277553 | AZ13: =AW13/AX12-1 -> 0.0087997692 | BA13: =AX13/AW13-1 -> -0.013013013 | BB13: =AZ13-BA13 -> 0.021812782 | BE13: 44215 | BF13: 127.78 | BG13: 127.83 | BH13: =BG13/BG12-1 -> 0.0054270882 | BI13: =BF13/BG12-1 -> 0.005033821 | BJ13: =BG13/BF13-1 -> 0.00039129754 | BK13: =BI13-BJ13 -> 0.0046425234 | BN13: 44215 | BO13: 213.75 | BP13: 216.44 | BQ13: =BP13/BP12-1 -> 0.017822713 | BR13: =BO13/BP12-1 -> 0.0051728192 | BS13: =BP13/BO13-1 -> 0.012584795 | BT13: =BR13-BS13 -> -0.0074119761 | BW13: 44215 | BX13: 48.21 | BY13: 47.8 | BZ13: =BY13/BY12-1 -> -0.0085044597 | CA13: =BX13/BY12-1 -> 0 | CB13: =BY13/BX13-1 -> -0.0085044597 | CC13: =CA13-CB13 -> 0.0085044597 | CF13: 44215 | CG13: 48.74 | CH13: 48.51 | CI13: =CH13/CH12-1 -> -0.0039014374 | CJ13: =CG13/CH12-1 -> 0.00082135524 | CK13: =CH13/CG13-1 -> -0.0047189167 | CL13: =CJ13-CK13 -> 0.0055402719
C14: 44216 | D14: 85.93 | E14: 83.5 | F14: =E14/E13-1 -> -0.023391813 | G14: =D14/E13-1 -> 0.0050292398 | H14: =E14/D14-1 -> -0.028278832 | I14: =G14-H14 -> 0.033308071 | L14: 44216 | M14: 13.11 | N14: 13.37 | O14: =N14/N13-1 -> 0.02609363 | P14: =M14/N13-1 -> 0.0061396777 | Q14: =N14/M14-1 -> 0.019832189 | R14: =P14-Q14 -> -0.013692512 | U14: 44216 | V14: 10.23 | W14: 10.86 | X14: =W14/W13-1 -> 0.083832335 | Y14: =V14/W13-1 -> 0.020958084 | Z14: =W14/V14-1 -> 0.061583578 | AA14: =Y14-Z14 -> -0.040625494 | AD14: 44216 | AE14: 192.66 | AF14: 192.34 | AG14: =AF14/AF13-1 -> -0.0088632382 | AH14: =AE14/AF13-1 -> -0.0072142636 | AI14: =AF14/AE14-1 -> -0.0016609571 | AJ14: =AH14-AI14 -> -0.0055533065 | AM14: 44216 | AN14: 49.11 | AO14: 49.53 | AP14: =AO14/AO13-1 -> 0.014127764 | AQ14: =AN14/AO13-1 -> 0.0055282555 | AR14: =AO14/AN14-1 -> 0.0085522297 | AS14: =AQ14-AR14 -> -0.0030239742 | AV14: 44216 | AW14: 137.82 | AX14: 135.97 | AY14: =AX14/AX13-1 -> -0.014995653 | AZ14: =AW14/AX13-1 -> -0.0015937409 | BA14: =AX14/AW14-1 -> -0.013423306 | BB14: =AZ14-BA14 -> 0.011829565 | BE14: 44216 | BF14: 128.66 | BG14: 132.03 | BH14: =BG14/BG13-1 -> 0.032856137 | BI14: =BF14/BG13-1 -> 0.0064929985 | BJ14: =BG14/BF14-1 -> 0.026193067 | BK14: =BI14-BJ14 -> -0.019700068 | BN14: 44216 | BO14: 217.7 | BP14: 224.34 | BQ14: =BP14/BP13-1 -> 0.036499723 | BR14: =BO14/BP13-1 -> 0.0058214748 | BS14: =BP14/BO14-1 -> 0.030500689 | BT14: =BR14-BS14 -> -0.024679214 | BW14: 44216 | BX14: 47.86 | BY14: 48.5 | BZ14: =BY14/BY13-1 -> 0.014644351 | CA14: =BX14/BY13-1 -> 0.0012552301 | CB14: =BY14/BX14-1 -> 0.013372336 | CC14: =CA14-CB14 -> -0.012117106 | CF14: 44216 | CG14: 48.54 | CH14: 48.68 | CI14: =CH14/CH13-1 -> 0.0035044321 | CJ14: =CG14/CH13-1 -> 0.00061842919 | CK14: =CH14/CG14-1 -> 0.0028842192 | CL14: =CJ14-CK14 -> -0.00226579
C15: 44217 | D15: 84 | E15: 85.01 | F15: =E15/E14-1 -> 0.018083832 | G15: =D15/E14-1 -> 0.005988024 | H15: =E15/D15-1 -> 0.01202381 | I15: =G15-H15 -> -0.0060357856 | L15: 44217 | M15: 13.42 | N15: 13.87 | O15: =N15/N14-1 -> 0.037397158 | P15: =M15/N14-1 -> 0.0037397158 | Q15: =N15/M15-1 -> 0.033532042 | R15: =P15-Q15 -> -0.029792326 | U15: 44217 | V15: 11.28 | W15: 11.53 | X15: =W15/W14-1 -> 0.061694291 | Y15: =V15/W14-1 -> 0.038674033 | Z15: =W15/V15-1 -> 0.022163121 | AA15: =Y15-Z15 -> 0.016510913 | AD15: 44217 | AE15: 192.35 | AF15: 192.19 | AG15: =AF15/AF14-1 -> -0.00077986898 | AH15: =AE15/AF14-1 -> 5.1991265e-05 | AI15: =AF15/AE15-1 -> -0.000831817 | AJ15: =AH15-AI15 -> 0.00088380827 | AM15: 44217 | AN15: 49.33 | AO15: 48.11 | AP15: =AO15/AO14-1 -> -0.028669493 | AQ15: =AN15/AO14-1 -> -0.0040379568 | AR15: =AO15/AN15-1 -> -0.024731401 | AS15: =AQ15-AR15 -> 0.020693444 | AV15: 44217 | AW15: 135.69 | AX15: 134.83 | AY15: =AX15/AX14-1 -> -0.0083842024 | AZ15: =AW15/AX14-1 -> -0.0020592778 | BA15: =AX15/AW15-1 -> -0.0063379763 | BB15: =AZ15-BA15 -> 0.0042786985 | BE15: 44217 | BF15: 133.8 | BG15: 136.87 | BH15: =BG15/BG14-1 -> 0.036658335 | BI15: =BF15/BG14-1 -> 0.013406044 | BJ15: =BG15/BF15-1 -> 0.022944694 | BK15: =BI15-BJ15 -> -0.0095386495 | BN15: 44217 | BO15: 224.7 | BP15: 224.97 | BQ15: =BP15/BP14-1 -> 0.0028082375 | BR15: =BO15/BP14-1 -> 0.0016047071 | BS15: =BP15/BO15-1 -> 0.0012016021 | BT15: =BR15-BS15 -> 0.000403105 | BW15: 44217 | BX15: 48.45 | BY15: 48.28 | BZ15: =BY15/BY14-1 -> -0.0045360825 | CA15: =BX15/BY14-1 -> -0.0010309278 | CB15: =BY15/BX15-1 -> -0.0035087719 | CC15: =CA15-CB15 -> 0.0024778441 | CF15: 44217 | CG15: 48.78 | CH15: 48.95 | CI15: =CH15/CH14-1 -> 0.0055464256 | CJ15: =CG15/CH14-1 -> 0.0020542317 | CK15: =CH15/CG15-1 -> 0.0034850349 | CL15: =CJ15-CK15 -> -0.0014308031
... C1257: 46022 | D1257: 293.17 | E1257: 285.41 | F1257: =E1257/E1256-1 -> -0.024672795 | G1257: =D1257/E1256-1 -> 0.0018453337 | H1257: =E1257/D1257-1 -> -0.026469284 | I1257: =G1257-H1257 -> 0.028314618 | L1257: 46022 | M1257: 189.57 | N1257: 186.5 | O1257: =N1257/N1256-1 -> -0.0055454836 | P1257: =M1257/N1256-1 -> 0.010824357 | Q1257: =N1257/M1257-1 -> -0.016194546 | R1257: =P1257-Q1257 -> 0.027018903 | U1257: 46022 | V1257: 13.21 | W1257: 13.12 | X1257: =W1257/W1256-1 -> -0.0083144369 | Y1257: =V1257/W1256-1 -> -0.0015117158 | Z1257: =W1257/V1257-1 -> -0.0068130204 | AA1257: =Y1257-Z1257 -> 0.0053013046 | AD1257: 46022 | AE1257: 577.3 | AF1257: 572.87 | AG1257: =AF1257/AF1256-1 -> -0.0078283309 | AH1257: =AE1257/AF1256-1 -> -0.00015587385 | AI1257: =AF1257/AE1257-1 -> -0.0076736532 | AJ1257: =AH1257-AI1257 -> 0.0075177794 | AM1257: 46022 | AN1257: 121.18 | AO1257: 120.34 | AP1257: =AO1257/AO1256-1 -> -0.0053723448 | AQ1257: =AN1257/AO1256-1 -> 0.0015703777 | AR1257: =AO1257/AN1257-1 -> -0.0069318369 | AS1257: =AQ1257-AR1257 -> 0.0085022147 | AV1257: 46022 | AW1257: 324.34 | AX1257: 322.22 | AY1257: =AX1257/AX1256-1 -> -0.0037103457 | AZ1257: =AW1257/AX1256-1 -> 0.0028445984 | BA1257: =AX1257/AW1257-1 -> -0.0065363507 | BB1257: =AZ1257-BA1257 -> 0.0093809491 | BE1257: 46022 | BF1257: 273.06 | BG1257: 271.86 | BH1257: =BG1257/BG1256-1 -> -0.0044675553 | BI1257: =BF1257/BG1256-1 -> -7.3238611e-05 | BJ1257: =BG1257/BF1257-1 -> -0.0043946385 | BK1257: =BI1257-BJ1257 -> 0.0043213999 | BN1257: 46022 | BO1257: 487.84 | BP1257: 483.62 | BQ1257: =BP1257/BP1256-1 -> -0.0079182736 | BR1257: =BO1257/BP1256-1 -> 0.00073849184 | BS1257: =BP1257/BO1257-1 -> -0.0086503772 | BT1257: =BR1257-BS1257 -> 0.009388869 | BW1257: 46022 | BX1257: 111.73 | BY1257: 111.41 | BZ1257: =BY1257/BY1256-1 -> -0.0045568263 | CA1257: =BX1257/BY1256-1 -> -0.0016976412 | CB1257: =BY1257/BX1257-1 -> -0.0028640473 | CC1257: =CA1257-CB1257 -> 0.0011664061 | CF1257: 46022 | CG1257: 70.07 | CH1257: 69.91 | CI1257: =CH1257/CH1256-1 -> -0.0022834309 | CJ1257: =CG1257/CH1256-1 -> 0 | CK1257: =CH1257/CG1257-1 -> -0.0022834309 | CL1257: =CJ1257-CK1257 -> 0.0022834309

Sheet Raw Data Adj Closes
B2: Ticker | C2: Date | D2: Adj Close | F2: Ticker | G2: Date | H2: Adj Close | J2: Ticker | K2: Date | L2: Adj Close | N2: Ticker | O2: Date | P2: Adj Close | R2: Ticker | S2: Date | T2: Adj Close | V2: Ticker | W2: Date | X2: Adj Close | Z2: Ticker | AA2: Date | AB2: Adj Close | AD2: Ticker | AE2: Date | AF2: Adj Close | AH2: Ticker | AI2: Date | AJ2: Adj Close | AL2: Ticker | AM2: Date | AN2: Adj Close | AP2: Ticker | AQ2: Date | AR2: Adj Close
B3: SPY | C3: 44200 | D3: 3700.65 | F3: MU | G3: 44200 | H3: 72.21 | J3: NVDA | K3: 44200 | L3: 13.06 | N3: F | O3: 44200 | P3: 6.25 | R3: CAT | S3: 44200 | T3: 164.62 | V3: XOM | W3: 44200 | X3: 33.25 | Z3: JPM | AA3: 44200 | AB3: 109 | AD3: AAPL | AE3: 44200 | AF3: 125.63 | AH3: MSFT | AI3: 44200 | AJ3: 207.57 | AL3: WMT | AM3: 44200 | AN3: 45.35 | AP3: KO | AQ3: 44200 | AR3: 44.79
C4: 44201 | D4: 3726.86 | G4: 44201 | H4: 75.34 | K4: 44201 | L4: 13.35 | O4: 44201 | P4: 6.34 | S4: 44201 | T4: 165.97 | W4: 44201 | X4: 34.85 | AA4: 44201 | AB4: 109.59 | AE4: 44201 | AF4: 127.19 | AI4: 44201 | AJ4: 207.77 | AM4: 44201 | AN4: 45.1 | AQ4: 44201 | AR4: 44.3
C5: 44202 | D5: 3748.14 | G5: 44202 | H5: 75.19 | K5: 44202 | L5: 12.56 | O5: 44202 | P5: 6.48 | S5: 44202 | T5: 175.21 | W5: 44202 | X5: 35.74 | AA5: 44202 | AB5: 114.74 | AE5: 44202 | AF5: 122.9 | AI5: 44202 | AJ5: 202.38 | AM5: 44202 | AN5: 45.39 | AQ5: 44202 | AR5: 42.89
C6: 44203 | D6: 3803.79 | G6: 44203 | H6: 77.14 | K6: 44203 | L6: 13.29 | O6: 44203 | P6: 6.64 | S6: 44203 | T6: 175.54 | W6: 44203 | X6: 36.02 | AA6: 44203 | AB6: 118.51 | AE6: 44203 | AF6: 127.1 | AI6: 44203 | AJ6: 208.14 | AM6: 44203 | AN6: 45.38 | AQ6: 44203 | AR6: 42.42
C7: 44204 | D7: 3824.68 | G7: 44204 | H7: 75.5 | K7: 44204 | L7: 13.22 | O7: 44204 | P7: 6.6 | S7: 44204 | T7: 175.57 | W7: 44204 | X7: 36.42 | AA7: 44204 | AB7: 118.64 | AE7: 44204 | AF7: 128.2 | AI7: 44204 | AJ7: 209.41 | AM7: 44204 | AN7: 45.38 | AQ7: 44204 | AR7: 43.37
C8: 44207 | D8: 3799.61 | G8: 44207 | H8: 76.71 | K8: 44207 | L8: 13.57 | O8: 44207 | P8: 6.82 | S8: 44207 | T8: 175.21 | W8: 44207 | X8: 37.53 | AA8: 44207 | AB8: 120.41 | AE8: 44207 | AF8: 125.22 | AI8: 44207 | AJ8: 207.37 | AM8: 44207 | AN8: 45.58 | AQ8: 44207 | AR8: 42.62
C9: 44208 | D9: 3801.19 | G9: 44208 | H9: 77.48 | K9: 44208 | L9: 13.43 | O9: 44208 | P9: 7.17 | S9: 44208 | T9: 178.53 | W9: 44208 | X9: 38.36 | AA9: 44208 | AB9: 122.3 | AE9: 44208 | AF9: 125.04 | AI9: 44208 | AJ9: 204.93 | AM9: 44208 | AN9: 46.1 | AQ9: 44208 | AR9: 42.54
C10: 44209 | D10: 3809.84 | G10: 44209 | H10: 77.92 | K10: 44209 | L10: 13.48 | O10: 44209 | P10: 7.17 | S10: 44209 | T10: 177.04 | W10: 44209 | X10: 38.8 | AA10: 44209 | AB10: 122.42 | AE10: 44209 | AF10: 127.07 | AI10: 44209 | AJ10: 206.28 | AM10: 44209 | AN10: 45.63 | AQ10: 44209 | AR10: 42.59
C11: 44210 | D11: 3795.54 | G11: 44210 | H11: 79.28 | K11: 44210 | L11: 13.15 | O11: 44210 | P11: 7.46 | S11: 44210 | T11: 178.41 | W11: 44210 | X11: 40.31 | AA11: 44210 | AB11: 123.13 | AE11: 44210 | AF11: 125.15 | AI11: 44210 | AJ11: 203.11 | AM11: 44210 | AN11: 45.48 | AQ11: 44210 | AR11: 41.8
C12: 44211 | D12: 3768.25 | G12: 44211 | H12: 78.71 | K12: 44211 | L12: 12.81 | O12: 44211 | P12: 7.21 | S12: 44211 | T12: 175.89 | W12: 44211 | X12: 38.37 | AA12: 44211 | AB12: 120.92 | AE12: 44211 | AF12: 123.43 | AI12: 44211 | AJ12: 202.76 | AM12: 44211 | AN12: 44.76 | AQ12: 44211 | AR12: 41.35
C13: 44215 | D13: 3798.91 | G13: 44215 | H13: 83.37 | K13: 44215 | L13: 12.97 | O13: 44215 | P13: 7.35 | S13: 44215 | T13: 176.32 | W13: 44215 | X13: 39.13 | AA13: 44215 | AB13: 120.4 | AE13: 44215 | AF13: 124.1 | AI13: 44215 | AJ13: 206.37 | AM13: 44215 | AN13: 44.37 | AQ13: 44215 | AR13: 41.18
C14: 44216 | D14: 3851.85 | G14: 44216 | H14: 81.42 | K14: 44216 | L14: 13.31 | O14: 44216 | P14: 7.96 | S14: 44216 | T14: 174.76 | W14: 44216 | X14: 39.69 | AA14: 44216 | AB14: 118.59 | AE14: 44216 | AF14: 128.18 | AI14: 44216 | AJ14: 213.91 | AM14: 44216 | AN14: 45.03 | AQ14: 44216 | AR14: 41.33
C15: 44217 | D15: 3853.07 | G15: 44217 | H15: 82.9 | K15: 44217 | L15: 13.81 | O15: 44217 | P15: 8.46 | S15: 44217 | T15: 174.62 | W15: 44217 | X15: 38.55 | AA15: 44217 | AB15: 117.6 | AE15: 44217 | AF15: 132.87 | AI15: 44217 | AJ15: 214.51 | AM15: 44217 | AN15: 44.83 | AQ15: 44217 | AR15: 41.56
... C1257: 46022 | D1257: 6845.5 | G1257: 46022 | H1257: 285.25 | K1257: 46022 | L1257: 186.27 | O1257: 46022 | P1257: 13.21 | S1257: 46022 | T1257: 577.3 | W1257: 46022 | X1257: 121.18 | AA1257: 46022 | AB1257: 324.34 | AE1257: 46022 | AF1257: 273.06 | AI1257: 46022 | AJ1257: 487.84 | AM1257: 46022 | AN1257: 111.73 | AQ1257: 46022 | AR1257: 70.07

Sheet Beta
C2: Beta Table
C3: Ticker | D3: Beta
C4: MU | D4: =K17 -> 1.773365
C5: NVDA | D5: =Q17 -> 2.1650239
C6: F | D6: =W17 -> 1.233301
C7: CAT | D7: =AC17 -> 0.98036315
C8: XOM | D8: =AI17 -> 0.54113944
C9: JPM | D9: =AO17 -> 0.89403394
C10: AAPL | D10: =AU17 -> 1.2444355
C11: MSFT | D11: =BA17 -> 1.1544142
C12: WMT | D12: =BG17 -> 0.45703754
C13: KO | D13: =BM17 -> 0.32188486
B16: Ticker | C16: Date | D16: Adj Close | E16: Daily Return | G16: Ticker | H16: Date | I16: Adj Close | J16: Daily Return | K16: Beta | M16: Ticker | N16: Date | O16: Adj Close | P16: Daily Return | Q16: Beta | S16: Ticker | T16: Date | U16: Adj Close | V16: Daily Return | W16: Beta | Y16: Ticker | Z16: Date | AA16: Adj Close | AB16: Daily Return | AC16: Beta | AE16: Ticker | AF16: Date | AG16: Adj Close | AH16: Daily Return | AI16: Beta | AK16: Ticker | AL16: Date | AM16: Adj Close | AN16: Daily Return | AO16: Beta | AQ16: Ticker | AR16: Date | AS16: Adj Close | AT16: Daily Return | AU16: Beta | AW16: Ticker | AX16: Date | AY16: Adj Close | AZ16: Daily Return | BA16: Beta | BC16: Ticker | BD16: Date | BE16: Adj Close | BF16: Daily Return | BG16: Beta | BI16: Ticker | BJ16: Date | BK16: Adj Close | BL16: Daily Return | BM16: Beta
B17: SPY | C17: 44200 | D17: 3700.65 | E17: reference | G17: MU | H17: 44200 | I17: 72.21 | J17: reference | K17: =SLOPE(J18:J1271,E18:E1271) -> 1.773365 | M17: NVDA | N17: 44200 | O17: 13.06 | P17: reference | Q17: =SLOPE(P18:P1271,E18:E1271) -> 2.1650239 | S17: F | T17: 44200 | U17: 6.25 | V17: reference | W17: =SLOPE(V18:V1271,E18:E1271) -> 1.233301 | Y17: CAT | Z17: 44200 | AA17: 164.62 | AB17: reference | AC17: =SLOPE(AB18:AB1271,E18:E1271) -> 0.98036315 | AE17: XOM | AF17: 44200 | AG17: 33.25 | AH17: reference | AI17: =SLOPE(AH18:AH1271,E18:E1271) -> 0.54113944 | AK17: JPM | AL17: 44200 | AM17: 109 | AN17: reference | AO17: =SLOPE(AN18:AN1271,E18:E1271) -> 0.89403394 | AQ17: AAPL | AR17: 44200 | AS17: 125.63 | AT17: reference | AU17: =SLOPE(AT18:AT1271,E18:E1271) -> 1.2444355 | AW17: MSFT | AX17: 44200 | AY17: 207.57 | AZ17: reference | BA17: =SLOPE(AZ18:AZ1271,E18:E1271) -> 1.1544142 | BC17: WMT | BD17: 44200 | BE17: 45.35 | BF17: reference | BG17: =SLOPE(BF18:BF1271,E18:E1271) -> 0.45703754 | BI17: KO | BJ17: 44200 | BK17: 44.79 | BL17: reference | BM17: =SLOPE(BL18:BL1271,E18:E1271) -> 0.32188486
C18: 44201 | D18: 3726.86 | E18: =D18/D17-1 -> 0.0070825396 | H18: 44201 | I18: 75.34 | J18: =I18/I17-1 -> 0.043345797 | K18: Check | N18: 44201 | O18: 13.35 | P18: =O18/O17-1 -> 0.022205207 | Q18: Check | T18: 44201 | U18: 6.34 | V18: =U18/U17-1 -> 0.0144 | W18: Check | Z18: 44201 | AA18: 165.97 | AB18: =AA18/AA17-1 -> 0.0082007047 | AC18: Check | AF18: 44201 | AG18: 34.85 | AH18: =AG18/AG17-1 -> 0.048120301 | AI18: Check | AL18: 44201 | AM18: 109.59 | AN18: =AM18/AM17-1 -> 0.005412844 | AO18: Check | AR18: 44201 | AS18: 127.19 | AT18: =AS18/AS17-1 -> 0.012417416 | AU18: Check | AX18: 44201 | AY18: 207.77 | AZ18: =AY18/AY17-1 -> 0.00096353038 | BA18: Check | BD18: 44201 | BE18: 45.1 | BF18: =BE18/BE17-1 -> -0.0055126792 | BG18: Check | BJ18: 44201 | BK18: 44.3 | BL18: =BK18/BK17-1 -> -0.010939942 | BM18: Check
C19: 44202 | D19: 3748.14 | E19: =D19/D18-1 -> 0.0057099006 | H19: 44202 | I19: 75.19 | J19: =I19/I18-1 -> -0.0019909743 | K19: =_xlfn.COVARIANCE.S(J18:J1271,E18:E1271)/_xlfn.VAR.S(E18:E1271) -> 1.773365 | N19: 44202 | O19: 12.56 | P19: =O19/O18-1 -> -0.05917603 | Q19: =_xlfn.COVARIANCE.S(P18:P1271,E18:E1271)/_xlfn.VAR.S(E18:E1271) -> 2.1650239 | T19: 44202 | U19: 6.48 | V19: =U19/U18-1 -> 0.022082019 | W19: =_xlfn.COVARIANCE.S(V18:V1271,E18:E1271)/_xlfn.VAR.S(E18:E1271) -> 1.233301 | Z19: 44202 | AA19: 175.21 | AB19: =AA19/AA18-1 -> 0.055672712 | AC19: =_xlfn.COVARIANCE.S(AB18:AB1271,E18:E1271)/_xlfn.VAR.S(E18:E1271) -> 0.98036315 | AF19: 44202 | AG19: 35.74 | AH19: =AG19/AG18-1 -> 0.02553802 | AI19: =_xlfn.COVARIANCE.S(AH18:AH1271,E18:E1271)/_xlfn.VAR.S(E18:E1271) -> 0.54113944 | AL19: 44202 | AM19: 114.74 | AN19: =AM19/AM18-1 -> 0.046993339 | AO19: =_xlfn.COVARIANCE.S(AN18:AN1271,E18:E1271)/_xlfn.VAR.S(E18:E1271) -> 0.89403394 | AR19: 44202 | AS19: 122.9 | AT19: =AS19/AS18-1 -> -0.033729067 | AU19: =_xlfn.COVARIANCE.S(AT18:AT1271,E18:E1271)/_xlfn.VAR.S(E18:E1271) -> 1.2444355 | AX19: 44202 | AY19: 202.38 | AZ19: =AY19/AY18-1 -> -0.025942148 | BA19: =_xlfn.COVARIANCE.S(AZ18:AZ1271,E18:E1271)/_xlfn.VAR.S(E18:E1271) -> 1.1544142 | BD19: 44202 | BE19: 45.39 | BF19: =BE19/BE18-1 -> 0.0064301552 | BG19: =_xlfn.COVARIANCE.S(BF18:BF1271,E18:E1271)/_xlfn.VAR.S(E18:E1271) -> 0.45703754 | BJ19: 44202 | BK19: 42.89 | BL19: =BK19/BK18-1 -> -0.031828442 | BM19: =_xlfn.COVARIANCE.S(BL18:BL1271,E18:E1271)/_xlfn.VAR.S(E18:E1271) -> 0.32188486
C20: 44203 | D20: 3803.79 | E20: =D20/D19-1 -> 0.014847364 | H20: 44203 | I20: 77.14 | J20: =I20/I19-1 -> 0.0259343 | N20: 44203 | O20: 13.29 | P20: =O20/O19-1 -> 0.058121019 | T20: 44203 | U20: 6.64 | V20: =U20/U19-1 -> 0.024691358 | Z20: 44203 | AA20: 175.54 | AB20: =AA20/AA19-1 -> 0.0018834541 | AF20: 44203 | AG20: 36.02 | AH20: =AG20/AG19-1 -> 0.0078343593 | AL20: 44203 | AM20: 118.51 | AN20: =AM20/AM19-1 -> 0.032856894 | AR20: 44203 | AS20: 127.1 | AT20: =AS20/AS19-1 -> 0.034174125 | AX20: 44203 | AY20: 208.14 | AZ20: =AY20/AY19-1 -> 0.02846131 | BD20: 44203 | BE20: 45.38 | BF20: =BE20/BE19-1 -> -0.00022031284 | BJ20: 44203 | BK20: 42.42 | BL20: =BK20/BK19-1 -> -0.010958265
C21: 44204 | D21: 3824.68 | E21: =D21/D20-1 -> 0.005491891 | H21: 44204 | I21: 75.5 | J21: =I21/I20-1 -> -0.021260047 | N21: 44204 | O21: 13.22 | P21: =O21/O20-1 -> -0.0052671181 | T21: 44204 | U21: 6.6 | V21: =U21/U20-1 -> -0.0060240964 | Z21: 44204 | AA21: 175.57 | AB21: =AA21/AA20-1 -> 0.00017090122 | AF21: 44204 | AG21: 36.42 | AH21: =AG21/AG20-1 -> 0.011104942 | AL21: 44204 | AM21: 118.64 | AN21: =AM21/AM20-1 -> 0.0010969538 | AR21: 44204 | AS21: 128.2 | AT21: =AS21/AS20-1 -> 0.0086546027 | AX21: 44204 | AY21: 209.41 | AZ21: =AY21/AY20-1 -> 0.0061016623 | BD21: 44204 | BE21: 45.38 | BF21: =BE21/BE20-1 -> 0 | BJ21: 44204 | BK21: 43.37 | BL21: =BK21/BK20-1 -> 0.022395097
C22: 44207 | D22: 3799.61 | E22: =D22/D21-1 -> -0.0065547967 | H22: 44207 | I22: 76.71 | J22: =I22/I21-1 -> 0.01602649 | N22: 44207 | O22: 13.57 | P22: =O22/O21-1 -> 0.026475038 | T22: 44207 | U22: 6.82 | V22: =U22/U21-1 -> 0.033333333 | Z22: 44207 | AA22: 175.21 | AB22: =AA22/AA21-1 -> -0.0020504642 | AF22: 44207 | AG22: 37.53 | AH22: =AG22/AG21-1 -> 0.030477759 | AL22: 44207 | AM22: 120.41 | AN22: =AM22/AM21-1 -> 0.014919083 | AR22: 44207 | AS22: 125.22 | AT22: =AS22/AS21-1 -> -0.02324493 | AX22: 44207 | AY22: 207.37 | AZ22: =AY22/AY21-1 -> -0.0097416551 | BD22: 44207 | BE22: 45.58 | BF22: =BE22/BE21-1 -> 0.0044072279 | BJ22: 44207 | BK22: 42.62 | BL22: =BK22/BK21-1 -> -0.01729306
C23: 44208 | D23: 3801.19 | E23: =D23/D22-1 -> 0.00041583215 | H23: 44208 | I23: 77.48 | J23: =I23/I22-1 -> 0.010037805 | N23: 44208 | O23: 13.43 | P23: =O23/O22-1 -> -0.010316875 | T23: 44208 | U23: 7.17 | V23: =U23/U22-1 -> 0.051319648 | Z23: 44208 | AA23: 178.53 | AB23: =AA23/AA22-1 -> 0.01894869 | AF23: 44208 | AG23: 38.36 | AH23: =AG23/AG22-1 -> 0.022115641 | AL23: 44208 | AM23: 122.3 | AN23: =AM23/AM22-1 -> 0.015696371 | AR23: 44208 | AS23: 125.04 | AT23: =AS23/AS22-1 -> -0.0014374701 | AX23: 44208 | AY23: 204.93 | AZ23: =AY23/AY22-1 -> -0.011766408 | BD23: 44208 | BE23: 46.1 | BF23: =BE23/BE22-1 -> 0.011408513 | BJ23: 44208 | BK23: 42.54 | BL23: =BK23/BK22-1 -> -0.001877053
C24: 44209 | D24: 3809.84 | E24: =D24/D23-1 -> 0.0022756032 | H24: 44209 | I24: 77.92 | J24: =I24/I23-1 -> 0.0056788849 | N24: 44209 | O24: 13.48 | P24: =O24/O23-1 -> 0.0037230082 | T24: 44209 | U24: 7.17 | V24: =U24/U23-1 -> 0 | Z24: 44209 | AA24: 177.04 | AB24: =AA24/AA23-1 -> -0.0083459363 | AF24: 44209 | AG24: 38.8 | AH24: =AG24/AG23-1 -> 0.011470282 | AL24: 44209 | AM24: 122.42 | AN24: =AM24/AM23-1 -> 0.00098119379 | AR24: 44209 | AS24: 127.07 | AT24: =AS24/AS23-1 -> 0.016234805 | AX24: 44209 | AY24: 206.28 | AZ24: =AY24/AY23-1 -> 0.0065876153 | BD24: 44209 | BE24: 45.63 | BF24: =BE24/BE23-1 -> -0.010195228 | BJ24: 44209 | BK24: 42.59 | BL24: =BK24/BK23-1 -> 0.0011753644
C25: 44210 | D25: 3795.54 | E25: =D25/D24-1 -> -0.0037534385 | H25: 44210 | I25: 79.28 | J25: =I25/I24-1 -> 0.017453799 | N25: 44210 | O25: 13.15 | P25: =O25/O24-1 -> -0.024480712 | T25: 44210 | U25: 7.46 | V25: =U25/U24-1 -> 0.040446304 | Z25: 44210 | AA25: 178.41 | AB25: =AA25/AA24-1 -> 0.0077383642 | AF25: 44210 | AG25: 40.31 | AH25: =AG25/AG24-1 -> 0.038917526 | AL25: 44210 | AM25: 123.13 | AN25: =AM25/AM24-1 -> 0.0057997059 | AR25: 44210 | AS25: 125.15 | AT25: =AS25/AS24-1 -> -0.015109782 | AX25: 44210 | AY25: 203.11 | AZ25: =AY25/AY24-1 -> -0.015367462 | BD25: 44210 | BE25: 45.48 | BF25: =BE25/BE24-1 -> -0.003287311 | BJ25: 44210 | BK25: 41.8 | BL25: =BK25/BK24-1 -> -0.018548955
C26: 44211 | D26: 3768.25 | E26: =D26/D25-1 -> -0.0071900178 | H26: 44211 | I26: 78.71 | J26: =I26/I25-1 -> -0.0071897074 | N26: 44211 | O26: 12.81 | P26: =O26/O25-1 -> -0.025855513 | T26: 44211 | U26: 7.21 | V26: =U26/U25-1 -> -0.033512064 | Z26: 44211 | AA26: 175.89 | AB26: =AA26/AA25-1 -> -0.014124769 | AF26: 44211 | AG26: 38.37 | AH26: =AG26/AG25-1 -> -0.048127016 | AL26: 44211 | AM26: 120.92 | AN26: =AM26/AM25-1 -> -0.01794851 | AR26: 44211 | AS26: 123.43 | AT26: =AS26/AS25-1 -> -0.013743508 | AX26: 44211 | AY26: 202.76 | AZ26: =AY26/AY25-1 -> -0.0017232042 | BD26: 44211 | BE26: 44.76 | BF26: =BE26/BE25-1 -> -0.015831135 | BJ26: 44211 | BK26: 41.35 | BL26: =BK26/BK25-1 -> -0.01076555
C27: 44215 | D27: 3798.91 | E27: =D27/D26-1 -> 0.0081364028 | H27: 44215 | I27: 83.37 | J27: =I27/I26-1 -> 0.059204675 | N27: 44215 | O27: 12.97 | P27: =O27/O26-1 -> 0.012490242 | T27: 44215 | U27: 7.35 | V27: =U27/U26-1 -> 0.019417476 | Z27: 44215 | AA27: 176.32 | AB27: =AA27/AA26-1 -> 0.0024447098 | AF27: 44215 | AG27: 39.13 | AH27: =AG27/AG26-1 -> 0.019807141 | AL27: 44215 | AM27: 120.4 | AN27: =AM27/AM26-1 -> -0.0043003639 | AR27: 44215 | AS27: 124.1 | AT27: =AS27/AS26-1 -> 0.0054281779 | AX27: 44215 | AY27: 206.37 | AZ27: =AY27/AY26-1 -> 0.017804301 | BD27: 44215 | BE27: 44.37 | BF27: =BE27/BE26-1 -> -0.0087131367 | BJ27: 44215 | BK27: 41.18 | BL27: =BK27/BK26-1 -> -0.0041112455
C28: 44216 | D28: 3851.85 | E28: =D28/D27-1 -> 0.013935576 | H28: 44216 | I28: 81.42 | J28: =I28/I27-1 -> -0.023389709 | N28: 44216 | O28: 13.31 | P28: =O28/O27-1 -> 0.026214341 | T28: 44216 | U28: 7.96 | V28: =U28/U27-1 -> 0.082993197 | Z28: 44216 | AA28: 174.76 | AB28: =AA28/AA27-1 -> -0.0088475499 | AF28: 44216 | AG28: 39.69 | AH28: =AG28/AG27-1 -> 0.01431127 | AL28: 44216 | AM28: 118.59 | AN28: =AM28/AM27-1 -> -0.015033223 | AR28: 44216 | AS28: 128.18 | AT28: =AS28/AS27-1 -> 0.032876712 | AX28: 44216 | AY28: 213.91 | AZ28: =AY28/AY27-1 -> 0.036536318 | BD28: 44216 | BE28: 45.03 | BF28: =BE28/BE27-1 -> 0.014874915 | BJ28: 44216 | BK28: 41.33 | BL28: =BK28/BK27-1 -> 0.0036425449
C29: 44217 | D29: 3853.07 | E29: =D29/D28-1 -> 0.00031673092 | H29: 44217 | I29: 82.9 | J29: =I29/I28-1 -> 0.018177352 | N29: 44217 | O29: 13.81 | P29: =O29/O28-1 -> 0.03756574 | T29: 44217 | U29: 8.46 | V29: =U29/U28-1 -> 0.06281407 | Z29: 44217 | AA29: 174.62 | AB29: =AA29/AA28-1 -> -0.00080109865 | AF29: 44217 | AG29: 38.55 | AH29: =AG29/AG28-1 -> -0.0287226 | AL29: 44217 | AM29: 117.6 | AN29: =AM29/AM28-1 -> -0.0083480901 | AR29: 44217 | AS29: 132.87 | AT29: =AS29/AS28-1 -> 0.036589171 | AX29: 44217 | AY29: 214.51 | AZ29: =AY29/AY28-1 -> 0.002804918 | BD29: 44217 | BE29: 44.83 | BF29: =BE29/BE28-1 -> -0.0044414835 | BJ29: 44217 | BK29: 41.56 | BL29: =BK29/BK28-1 -> 0.0055649649
C30: 44218 | D30: 3841.47 | E30: =D30/D29-1 -> -0.0030105864 | H30: 44218 | I30: 80.23 | J30: =I30/I29-1 -> -0.032207479 | N30: 44218 | O30: 13.66 | P30: =O30/O29-1 -> -0.010861694 | T30: 44218 | U30: 8.45 | V30: =U30/U29-1 -> -0.0011820331 | Z30: 44218 | AA30: 174.39 | AB30: =AA30/AA29-1 -> -0.0013171458 | AF30: 44218 | AG30: 38 | AH30: =AG30/AG29-1 -> -0.014267185 | AL30: 44218 | AM30: 116.69 | AN30: =AM30/AM29-1 -> -0.0077380952 | AR30: 44218 | AS30: 135.01 | AT30: =AS30/AS29-1 -> 0.016105968 | AX30: 44218 | AY30: 215.44 | AZ30: =AY30/AY29-1 -> 0.0043354622 | BD30: 44218 | BE30: 45.28 | BF30: =BE30/BE29-1 -> 0.010037921 | BJ30: 44218 | BK30: 41.17 | BL30: =BK30/BK29-1 -> -0.0093840231
C31: 44221 | D31: 3855.36 | E31: =D31/D30-1 -> 0.0036158033 | H31: 44221 | I31: 79.26 | J31: =I31/I30-1 -> -0.012090241 | N31: 44221 | O31: 13.6 | P31: =O31/O30-1 -> -0.0043923865 | T31: 44221 | U31: 8.28 | V31: =U31/U30-1 -> -0.020118343 | Z31: 44221 | AA31: 170.22 | AB31: =AA31/AA30-1 -> -0.023911922 | AF31: 44221 | AG31: 37.58 | AH31: =AG31/AG30-1 -> -0.011052632 | AL31: 44221 | AM31: 115.24 | AN31: =AM31/AM30-1 -> -0.012426086 | AR31: 44221 | AS31: 138.75 | AT31: =AS31/AS30-1 -> 0.027701652 | AX31: 44221 | AY31: 218.85 | AZ31: =AY31/AY30-1 -> 0.015828073 | BD31: 44221 | BE31: 45.24 | BF31: =BE31/BE30-1 -> -0.00088339223 | BJ31: 44221 | BK31: 41.41 | BL31: =BK31/BK30-1 -> 0.0058294875
