Workbook
Name Avg_PE: Inputs!$C$8
Name Current_Level: Inputs!$C$3
Name Current_PE: Inputs!$C$7
Name Div_Yield: Inputs!$C$5
Name Inflation: Inputs!$C$6
Name Return_Growth: Inputs!$C$4
Name Volatility: Inputs!$C$10
Name Year_30: Charts!$AG$42:$AG$1041
Name Years: Inputs!$C$9

Sheet Inputs
B2: Date | C2: 46174 | E2: Working Name
B3: Starting Price Level | C3: 75 | E3: Current_Level | G3: (Extrapolated to beginning of month close)
B4: Expected Yearly Return | C4: 0.07 | E4: Yearly_Growth
B5: Dividend Yield | C5: 0.051 | E5: Div_Yield
B6: Inflation | C6: 0.024 | E6: Inflation
B7: Current Forward PE | C7: 9 | E7: Current_PE
B8: Historical Average PE | C8: 10 | E8: Avg_PE | F8: (Lowered to reflect mature growth)
B9: Projection Years | C9: 10 | E9: Years
B10: Expected Volatility | C10: 0.35 | E10: Volatility

Sheet Historical Data
B2: Date | C2: Adjusted Close | D2: Monthly Return | E2: Annualized Return | F2: Annualized Volatility
B3: 38869 | C3: 30.18 | D3: reference | E3: =AVERAGE(D:D)*12 -> 0.1189431 | F3: =_xlfn.STDEV.P(D:D)*SQRT(12) -> 0.3829959
B4: 38899 | C4: 24.96 | D4: =(C4/C3)-1 -> -0.17296223
B5: 38930 | C5: 25.87 | D5: =(C5/C4)-1 -> 0.036458333
B6: 38961 | C6: 29.53 | D6: =(C6/C5)-1 -> 0.14147661
B7: 38991 | C7: 30.46 | D7: =(C7/C6)-1 -> 0.031493397
B8: 39022 | C8: 30.31 | D8: =(C8/C7)-1 -> -0.0049244911
B9: 39052 | C9: 27.18 | D9: =(C9/C8)-1 -> -0.10326625
B10: 39083 | C10: 27.85 | D10: =(C10/C9)-1 -> 0.024650478
B11: 39114 | C11: 25.68 | D11: =(C11/C10)-1 -> -0.077917415
B12: 39142 | C12: 26.92 | D12: =(C12/C11)-1 -> 0.048286604
B13: 39173 | C13: 25.83 | D13: =(C13/C12)-1 -> -0.040490342
B14: 39203 | C14: 26.74 | D14: =(C14/C13)-1 -> 0.035230352
B15: 39234 | C15: 25.84 | D15: =(C15/C14)-1 -> -0.033657442
... B243: 46174 | C243: 75.88 | D243: =(C243/C242)-1 -> -0.013648772

Sheet Valuation
B2: Current PE | C2: =Current_PE -> 9
B3: Target PE | C3: =Avg_PE -> 10
B4: Years | C4: =Years -> 10
B5: Valuation Drag | C5: =(C3/C2)^(1/C4)-1 -> 0.010591751

Sheet Projection Engine
B2: Expected Return | E2: Forward Projection | H2: Inflation Adjusted
E3: Year | F3: Price Level ($) | H3: Real Return | I3: Year | J3: Inflation Adjusted Index Level
B4: Yearly Growth | C4: =Return_Growth -> 0.07 | E4: 0 | F4: =Current_Level -> 75 | H4: =(1+$C$8)/(1+Inflation)-1 -> 0.10507007 | I4: 0 | J4: =Current_Level -> 75
B5: Dividend Yield | C5: =Div_Yield -> 0.051 | E5: 1 | F5: =F4*(1+$C$8) -> 84.869381 | I5: 1 | J5: =J4*(1+$H$4) -> 82.880255
B6: Valuation Effect | C6: =Valuation!C5 -> 0.010591751 | E6: 2 | F6: =F5*(1+$C$8) -> 96.037492 | I6: 2 | J6: =J5*(1+$H$4) -> 91.588489
E7: 3 | F7: =F6*(1+$C$8) -> 108.67523 | I7: 3 | J7: =J6*(1+$H$4) -> 101.2117
B8: Total Expected Return | C8: =SUM(C4:C6) -> 0.13159175 | E8: 4 | F8: =F7*(1+$C$8) -> 122.976 | I8: 4 | J8: =J7*(1+$H$4) -> 111.84602
E9: 5 | F9: =F8*(1+$C$8) -> 139.15862 | I9: 5 | J9: =J8*(1+$H$4) -> 123.59769
E10: 6 | F10: =F9*(1+$C$8) -> 157.47075 | I10: 6 | J10: =J9*(1+$H$4) -> 136.58411
E11: 7 | F11: =F10*(1+$C$8) -> 178.1926 | I11: 7 | J11: =J10*(1+$H$4) -> 150.93501
E12: 8 | F12: =F11*(1+$C$8) -> 201.64128 | I12: 8 | J12: =J11*(1+$H$4) -> 166.79376
E13: 9 | F13: =F12*(1+$C$8) -> 228.17561 | I13: 9 | J13: =J12*(1+$H$4) -> 184.31879
E14: 10 | F14: =F13*(1+$C$8) -> 258.20164 | I14: 10 | J14: =J13*(1+$H$4) -> 203.68518

Sheet Scenarios
B2: Scenario | C2: Growth | D2: Yield | E2: Valuation | F2: Total Return | G2: 10 Year Price Level
B3: Bear | C3: 0.05 | D3: =Div_Yield -> 0.051 | E3: 0 | F3: =SUM(C3:E3) -> 0.101 | G3: =Current_Level*(1+F3)^Years -> 196.3064
B4: Base | C4: =Return_Growth -> 0.07 | D4: =Div_Yield -> 0.051 | E4: =Valuation!C5 -> 0.010591751 | F4: =SUM(C4:E4) -> 0.13159175 | G4: =Current_Level*(1+F4)^Years -> 258.20164
B5: Bull | C5: 0.09 | D5: =Div_Yield -> 0.051 | E5: 0.02 | F5: =SUM(C5:E5) -> 0.161 | G5: =Current_Level*(1+F5)^Years -> 333.72094
B7: 10 Year Projection
C8: Total Return | E8: Year | F8: Bear BBY | G8: Base BBY | H8: Bull BBY
B9: Bear | C9: =F3 -> 0.101 | E9: 0 | F9: =Current_Level -> 75 | G9: =Current_Level -> 75 | H9: =Current_Level -> 75
B10: Base | C10: =F4 -> 0.13159175 | E10: 1 | F10: =F9*(1+$C$9) -> 82.575 | G10: =G9*(1+$C$10) -> 84.869381 | H10: =H9*(1+$C$11) -> 87.075
B11: Bull | C11: =F5 -> 0.161 | E11: 2 | F11: =F10*(1+$C$9) -> 90.915075 | G11: =G10*(1+$C$10) -> 96.037492 | H11: =H10*(1+$C$11) -> 101.09408
E12: 3 | F12: =F11*(1+$C$9) -> 100.0975 | G12: =G11*(1+$C$10) -> 108.67523 | H12: =H11*(1+$C$11) -> 117.37022
E13: 4 | F13: =F12*(1+$C$9) -> 110.20734 | G13: =G12*(1+$C$10) -> 122.976 | H13: =H12*(1+$C$11) -> 136.26683
E14: 5 | F14: =F13*(1+$C$9) -> 121.33829 | G14: =G13*(1+$C$10) -> 139.15862 | H14: =H13*(1+$C$11) -> 158.20579
E15: 6 | F15: =F14*(1+$C$9) -> 133.59345 | G15: =G14*(1+$C$10) -> 157.47075 | H15: =H14*(1+$C$11) -> 183.67692
E16: 7 | F16: =F15*(1+$C$9) -> 147.08639 | G16: =G15*(1+$C$10) -> 178.1926 | H16: =H15*(1+$C$11) -> 213.2489
E17: 8 | F17: =F16*(1+$C$9) -> 161.94212 | G17: =G16*(1+$C$10) -> 201.64128 | H17: =H16*(1+$C$11) -> 247.58197
E18: 9 | F18: =F17*(1+$C$9) -> 178.29827 | G18: =G17*(1+$C$10) -> 228.17561 | H18: =H17*(1+$C$11) -> 287.44267
E19: 10 | F19: =F18*(1+$C$9) -> 196.3064 | G19: =G18*(1+$C$10) -> 258.20164 | H19: =H18*(1+$C$11) -> 333.72094

Sheet Monte Carlo
C2: Year 0 | D2: Year 1 | E2: Year 2 | F2: Year 3 | G2: Year 4 | H2: Year 5 | I2: Year 6 | J2: Year 7 | K2: Year 8 | L2: Year 9 | M2: Year 10 | N2: Year 11 | O2: Year 12 | P2: Year 13 | Q2: Year 14 | R2: Year 15 | S2: Year 16 | T2: Year 17 | U2: Year 18 | V2: Year 19 | W2: Year 20 | X2: Year 21 | Y2: Year 22 | Z2: Year 23 | AA2: Year 24 | AB2: Year 25 | AC2: Year 26 | AD2: Year 27 | AE2: Year 28 | AF2: Year 29 | AG2: Year 30
B3: Simulation 1 | C3: =Current_Level -> 75 | D3: =C3*EXP(_xlfn.NORM.INV(RAND(),'Projection Engine'!$C$8-(Volatility^2/2),Volatility)) -> 80.304301 | E3: =D3*EXP(_xlfn.NORM.INV(RAND(),'Projection Engine'!$C$8-(Volatility^2/2),Volatility)) -> 55.613564 | F3: =E3*EXP(_xlfn.NORM.INV(RAND(),'Projection Engine'!$C$8-(Volatility^2/2),Volatility)) -> 34.024 | G3: =F3*EXP(_xlfn.NORM.INV(RAND(),'Projection Engine'!$C$8-(Volatility^2/2),Volatility)) -> 26.718795 | H3: =G3*EXP(_xlfn.NORM.INV(RAND(),'Projection Engine'!$C$8-(Volatility^2/2),Volatility)) -> 44.979085 | I3: =H3*EXP(_xlfn.NORM.INV(RAND(),'Projection Engine'!$C$8-(Volatility^2/2),Volatility)) -> 56.177539 | J3: =I3*EXP(_xlfn.NORM.INV(RAND(),'Projection Engine'!$C$8-(Volatility^2/2),Volatility)) -> 51.065322 | K3: =J3*EXP(_xlfn.NORM.INV(RAND(),'Projection Engine'!$C$8-(Volatility^2/2),Volatility)) -> 45.83458 | ... AG3: =AF3*EXP(_xlfn.NORM.INV(RAND(),'Projection Engine'!$C$8-(Volatility^2/2),Volatility)) -> 1492.3266
B4: Simulation 2 | C4: =Current_Level -> 75 | D4: =C4*EXP(_xlfn.NORM.INV(RAND(),'Projection Engine'!$C$8-(Volatility^2/2),Volatility)) -> 118.21413 | E4: =D4*EXP(_xlfn.NORM.INV(RAND(),'Projection Engine'!$C$8-(Volatility^2/2),Volatility)) -> 137.7743 | F4: =E4*EXP(_xlfn.NORM.INV(RAND(),'Projection Engine'!$C$8-(Volatility^2/2),Volatility)) -> 99.050191 | G4: =F4*EXP(_xlfn.NORM.INV(RAND(),'Projection Engine'!$C$8-(Volatility^2/2),Volatility)) -> 73.678796 | H4: =G4*EXP(_xlfn.NORM.INV(RAND(),'Projection Engine'!$C$8-(Volatility^2/2),Volatility)) -> 99.171943 | I4: =H4*EXP(_xlfn.NORM.INV(RAND(),'Projection Engine'!$C$8-(Volatility^2/2),Volatility)) -> 103.80896 | J4: =I4*EXP(_xlfn.NORM.INV(RAND(),'Projection Engine'!$C$8-(Volatility^2/2),Volatility)) -> 87.912732 | K4: =J4*EXP(_xlfn.NORM.INV(RAND(),'Projection Engine'!$C$8-(Volatility^2/2),Volatility)) -> 98.210571 | ... AG4: =AF4*EXP(_xlfn.NORM.INV(RAND(),'Projection Engine'!$C$8-(Volatility^2/2),Volatility)) -> 10166.743
B5: Simulation 3 | C5: =Current_Level -> 75 | D5: =C5*EXP(_xlfn.NORM.INV(RAND(),'Projection Engine'!$C$8-(Volatility^2/2),Volatility)) -> 103.76887 | E5: =D5*EXP(_xlfn.NORM.INV(RAND(),'Projection Engine'!$C$8-(Volatility^2/2),Volatility)) -> 75.046773 | F5: =E5*EXP(_xlfn.NORM.INV(RAND(),'Projection Engine'!$C$8-(Volatility^2/2),Volatility)) -> 75.6758 | G5: =F5*EXP(_xlfn.NORM.INV(RAND(),'Projection Engine'!$C$8-(Volatility^2/2),Volatility)) -> 55.984632 | H5: =G5*EXP(_xlfn.NORM.INV(RAND(),'Projection Engine'!$C$8-(Volatility^2/2),Volatility)) -> 67.866547 | I5: =H5*EXP(_xlfn.NORM.INV(RAND(),'Projection Engine'!$C$8-(Volatility^2/2),Volatility)) -> 48.766459 | J5: =I5*EXP(_xlfn.NORM.INV(RAND(),'Projection Engine'!$C$8-(Volatility^2/2),Volatility)) -> 63.504133 | K5: =J5*EXP(_xlfn.NORM.INV(RAND(),'Projection Engine'!$C$8-(Volatility^2/2),Volatility)) -> 90.077566 | ... AG5: =AF5*EXP(_xlfn.NORM.INV(RAND(),'Projection Engine'!$C$8-(Volatility^2/2),Volatility)) -> 610.87927
B6: Simulation 4 | C6: =Current_Level -> 75 | D6: =C6*EXP(_xlfn.NORM.INV(RAND(),'Projection Engine'!$C$8-(Volatility^2/2),Volatility)) -> 105.46066 | E6: =D6*EXP(_xlfn.NORM.INV(RAND(),'Projection Engine'!$C$8-(Volatility^2/2),Volatility)) -> 122.05227 | F6: =E6*EXP(_xlfn.NORM.INV(RAND(),'Projection Engine'!$C$8-(Volatility^2/2),Volatility)) -> 77.552616 | G6: =F6*EXP(_xlfn.NORM.INV(RAND(),'Projection Engine'!$C$8-(Volatility^2/2),Volatility)) -> 121.13245 | H6: =G6*EXP(_xlfn.NORM.INV(RAND(),'Projection Engine'!$C$8-(Volatility^2/2),Volatility)) -> 138.9281 | I6: =H6*EXP(_xlfn.NORM.INV(RAND(),'Projection Engine'!$C$8-(Volatility^2/2),Volatility)) -> 117.09515 | J6: =I6*EXP(_xlfn.NORM.INV(RAND(),'Projection Engine'!$C$8-(Volatility^2/2),Volatility)) -> 209.93096 | K6: =J6*EXP(_xlfn.NORM.INV(RAND(),'Projection Engine'!$C$8-(Volatility^2/2),Volatility)) -> 100.15034 | ... AG6: =AF6*EXP(_xlfn.NORM.INV(RAND(),'Projection Engine'!$C$8-(Volatility^2/2),Volatility)) -> 7707.4961
B7: Simulation 5 | C7: =Current_Level -> 75 | D7: =C7*EXP(_xlfn.NORM.INV(RAND(),'Projection Engine'!$C$8-(Volatility^2/2),Volatility)) -> 78.685055 | E7: =D7*EXP(_xlfn.NORM.INV(RAND(),'Projection Engine'!$C$8-(Volatility^2/2),Volatility)) -> 115.70081 | F7: =E7*EXP(_xlfn.NORM.INV(RAND(),'Projection Engine'!$C$8-(Volatility^2/2),Volatility)) -> 100.38492 | G7: =F7*EXP(_xlfn.NORM.INV(RAND(),'Projection Engine'!$C$8-(Volatility^2/2),Volatility)) -> 141.44361 | H7: =G7*EXP(_xlfn.NORM.INV(RAND(),'Projection Engine'!$C$8-(Volatility^2/2),Volatility)) -> 149.59216 | I7: =H7*EXP(_xlfn.NORM.INV(RAND(),'Projection Engine'!$C$8-(Volatility^2/2),Volatility)) -> 141.38676 | J7: =I7*EXP(_xlfn.NORM.INV(RAND(),'Projection Engine'!$C$8-(Volatility^2/2),Volatility)) -> 126.11604 | K7: =J7*EXP(_xlfn.NORM.INV(RAND(),'Projection Engine'!$C$8-(Volatility^2/2),Volatility)) -> 70.929964 | ... AG7: =AF7*EXP(_xlfn.NORM.INV(RAND(),'Projection Engine'!$C$8-(Volatility^2/2),Volatility)) -> 1371.0733
B8: Simulation 6 | C8: =Current_Level -> 75 | D8: =C8*EXP(_xlfn.NORM.INV(RAND(),'Projection Engine'!$C$8-(Volatility^2/2),Volatility)) -> 119.94647 | E8: =D8*EXP(_xlfn.NORM.INV(RAND(),'Projection Engine'!$C$8-(Volatility^2/2),Volatility)) -> 288.98297 | F8: =E8*EXP(_xlfn.NORM.INV(RAND(),'Projection Engine'!$C$8-(Volatility^2/2),Volatility)) -> 241.85036 | G8: =F8*EXP(_xlfn.NORM.INV(RAND(),'Projection Engine'!$C$8-(Volatility^2/2),Volatility)) -> 677.30426 | H8: =G8*EXP(_xlfn.NORM.INV(RAND(),'Projection Engine'!$C$8-(Volatility^2/2),Volatility)) -> 526.53446 | I8: =H8*EXP(_xlfn.NORM.INV(RAND(),'Projection Engine'!$C$8-(Volatility^2/2),Volatility)) -> 506.68787 | J8: =I8*EXP(_xlfn.NORM.INV(RAND(),'Projection Engine'!$C$8-(Volatility^2/2),Volatility)) -> 738.14124 | K8: =J8*EXP(_xlfn.NORM.INV(RAND(),'Projection Engine'!$C$8-(Volatility^2/2),Volatility)) -> 1229.653 | ... AG8: =AF8*EXP(_xlfn.NORM.INV(RAND(),'Projection Engine'!$C$8-(Volatility^2/2),Volatility)) -> 3451.7195
B9: Simulation 7 | C9: =Current_Level -> 75 | D9: =C9*EXP(_xlfn.NORM.INV(RAND(),'Projection Engine'!$C$8-(Volatility^2/2),Volatility)) -> 64.506541 | E9: =D9*EXP(_xlfn.NORM.INV(RAND(),'Projection Engine'!$C$8-(Volatility^2/2),Volatility)) -> 63.751813 | F9: =E9*EXP(_xlfn.NORM.INV(RAND(),'Projection Engine'!$C$8-(Volatility^2/2),Volatility)) -> 64.445742 | G9: =F9*EXP(_xlfn.NORM.INV(RAND(),'Projection Engine'!$C$8-(Volatility^2/2),Volatility)) -> 44.363014 | H9: =G9*EXP(_xlfn.NORM.INV(RAND(),'Projection Engine'!$C$8-(Volatility^2/2),Volatility)) -> 43.322823 | I9: =H9*EXP(_xlfn.NORM.INV(RAND(),'Projection Engine'!$C$8-(Volatility^2/2),Volatility)) -> 38.82031 | J9: =I9*EXP(_xlfn.NORM.INV(RAND(),'Projection Engine'!$C$8-(Volatility^2/2),Volatility)) -> 42.732489 | K9: =J9*EXP(_xlfn.NORM.INV(RAND(),'Projection Engine'!$C$8-(Volatility^2/2),Volatility)) -> 87.913896 | ... AG9: =AF9*EXP(_xlfn.NORM.INV(RAND(),'Projection Engine'!$C$8-(Volatility^2/2),Volatility)) -> 864.75433
B10: Simulation 8 | C10: =Current_Level -> 75 | D10: =C10*EXP(_xlfn.NORM.INV(RAND(),'Projection Engine'!$C$8-(Volatility^2/2),Volatility)) -> 109.74965 | E10: =D10*EXP(_xlfn.NORM.INV(RAND(),'Projection Engine'!$C$8-(Volatility^2/2),Volatility)) -> 116.91533 | F10: =E10*EXP(_xlfn.NORM.INV(RAND(),'Projection Engine'!$C$8-(Volatility^2/2),Volatility)) -> 130.79358 | G10: =F10*EXP(_xlfn.NORM.INV(RAND(),'Projection Engine'!$C$8-(Volatility^2/2),Volatility)) -> 126.15571 | H10: =G10*EXP(_xlfn.NORM.INV(RAND(),'Projection Engine'!$C$8-(Volatility^2/2),Volatility)) -> 88.331811 | I10: =H10*EXP(_xlfn.NORM.INV(RAND(),'Projection Engine'!$C$8-(Volatility^2/2),Volatility)) -> 117.52333 | J10: =I10*EXP(_xlfn.NORM.INV(RAND(),'Projection Engine'!$C$8-(Volatility^2/2),Volatility)) -> 201.36686 | K10: =J10*EXP(_xlfn.NORM.INV(RAND(),'Projection Engine'!$C$8-(Volatility^2/2),Volatility)) -> 220.60543 | ... AG10: =AF10*EXP(_xlfn.NORM.INV(RAND(),'Projection Engine'!$C$8-(Volatility^2/2),Volatility)) -> 2816.6454
B11: Simulation 9 | C11: =Current_Level -> 75 | D11: =C11*EXP(_xlfn.NORM.INV(RAND(),'Projection Engine'!$C$8-(Volatility^2/2),Volatility)) -> 108.24013 | E11: =D11*EXP(_xlfn.NORM.INV(RAND(),'Projection Engine'!$C$8-(Volatility^2/2),Volatility)) -> 150.58644 | F11: =E11*EXP(_xlfn.NORM.INV(RAND(),'Projection Engine'!$C$8-(Volatility^2/2),Volatility)) -> 279.55756 | G11: =F11*EXP(_xlfn.NORM.INV(RAND(),'Projection Engine'!$C$8-(Volatility^2/2),Volatility)) -> 319.0941 | H11: =G11*EXP(_xlfn.NORM.INV(RAND(),'Projection Engine'!$C$8-(Volatility^2/2),Volatility)) -> 267.25708 | I11: =H11*EXP(_xlfn.NORM.INV(RAND(),'Projection Engine'!$C$8-(Volatility^2/2),Volatility)) -> 307.05919 | J11: =I11*EXP(_xlfn.NORM.INV(RAND(),'Projection Engine'!$C$8-(Volatility^2/2),Volatility)) -> 356.37786 | K11: =J11*EXP(_xlfn.NORM.INV(RAND(),'Projection Engine'!$C$8-(Volatility^2/2),Volatility)) -> 497.14887 | ... AG11: =AF11*EXP(_xlfn.NORM.INV(RAND(),'Projection Engine'!$C$8-(Volatility^2/2),Volatility)) -> 4530.0208
B12: Simulation 10 | C12: =Current_Level -> 75 | D12: =C12*EXP(_xlfn.NORM.INV(RAND(),'Projection Engine'!$C$8-(Volatility^2/2),Volatility)) -> 72.415825 | E12: =D12*EXP(_xlfn.NORM.INV(RAND(),'Projection Engine'!$C$8-(Volatility^2/2),Volatility)) -> 95.696205 | F12: =E12*EXP(_xlfn.NORM.INV(RAND(),'Projection Engine'!$C$8-(Volatility^2/2),Volatility)) -> 72.533114 | G12: =F12*EXP(_xlfn.NORM.INV(RAND(),'Projection Engine'!$C$8-(Volatility^2/2),Volatility)) -> 115.55453 | H12: =G12*EXP(_xlfn.NORM.INV(RAND(),'Projection Engine'!$C$8-(Volatility^2/2),Volatility)) -> 188.39111 | I12: =H12*EXP(_xlfn.NORM.INV(RAND(),'Projection Engine'!$C$8-(Volatility^2/2),Volatility)) -> 120.79817 | J12: =I12*EXP(_xlfn.NORM.INV(RAND(),'Projection Engine'!$C$8-(Volatility^2/2),Volatility)) -> 128.37852 | K12: =J12*EXP(_xlfn.NORM.INV(RAND(),'Projection Engine'!$C$8-(Volatility^2/2),Volatility)) -> 98.649527 | ... AG12: =AF12*EXP(_xlfn.NORM.INV(RAND(),'Projection Engine'!$C$8-(Volatility^2/2),Volatility)) -> 50.838286
B13: Simulation 11 | C13: =Current_Level -> 75 | D13: =C13*EXP(_xlfn.NORM.INV(RAND(),'Projection Engine'!$C$8-(Volatility^2/2),Volatility)) -> 125.33115 | E13: =D13*EXP(_xlfn.NORM.INV(RAND(),'Projection Engine'!$C$8-(Volatility^2/2),Volatility)) -> 102.02377 | F13: =E13*EXP(_xlfn.NORM.INV(RAND(),'Projection Engine'!$C$8-(Volatility^2/2),Volatility)) -> 141.98844 | G13: =F13*EXP(_xlfn.NORM.INV(RAND(),'Projection Engine'!$C$8-(Volatility^2/2),Volatility)) -> 156.97461 | H13: =G13*EXP(_xlfn.NORM.INV(RAND(),'Projection Engine'!$C$8-(Volatility^2/2),Volatility)) -> 264.22343 | I13: =H13*EXP(_xlfn.NORM.INV(RAND(),'Projection Engine'!$C$8-(Volatility^2/2),Volatility)) -> 316.2105 | J13: =I13*EXP(_xlfn.NORM.INV(RAND(),'Projection Engine'!$C$8-(Volatility^2/2),Volatility)) -> 321.03464 | K13: =J13*EXP(_xlfn.NORM.INV(RAND(),'Projection Engine'!$C$8-(Volatility^2/2),Volatility)) -> 302.23286 | ... AG13: =AF13*EXP(_xlfn.NORM.INV(RAND(),'Projection Engine'!$C$8-(Volatility^2/2),Volatility)) -> 5696.0759
B14: Simulation 12 | C14: =Current_Level -> 75 | D14: =C14*EXP(_xlfn.NORM.INV(RAND(),'Projection Engine'!$C$8-(Volatility^2/2),Volatility)) -> 134.1566 | E14: =D14*EXP(_xlfn.NORM.INV(RAND(),'Projection Engine'!$C$8-(Volatility^2/2),Volatility)) -> 142.5372 | F14: =E14*EXP(_xlfn.NORM.INV(RAND(),'Projection Engine'!$C$8-(Volatility^2/2),Volatility)) -> 105.16506 | G14: =F14*EXP(_xlfn.NORM.INV(RAND(),'Projection Engine'!$C$8-(Volatility^2/2),Volatility)) -> 87.160484 | H14: =G14*EXP(_xlfn.NORM.INV(RAND(),'Projection Engine'!$C$8-(Volatility^2/2),Volatility)) -> 75.947577 | I14: =H14*EXP(_xlfn.NORM.INV(RAND(),'Projection Engine'!$C$8-(Volatility^2/2),Volatility)) -> 71.757024 | J14: =I14*EXP(_xlfn.NORM.INV(RAND(),'Projection Engine'!$C$8-(Volatility^2/2),Volatility)) -> 45.517556 | K14: =J14*EXP(_xlfn.NORM.INV(RAND(),'Projection Engine'!$C$8-(Volatility^2/2),Volatility)) -> 56.763425 | ... AG14: =AF14*EXP(_xlfn.NORM.INV(RAND(),'Projection Engine'!$C$8-(Volatility^2/2),Volatility)) -> 84.570656
... B1002: Simulation 1000 | C1002: =Current_Level -> 75 | D1002: =C1002*EXP(_xlfn.NORM.INV(RAND(),'Projection Engine'!$C$8-(Volatility^2/2),Volatility)) -> 93.784585 | E1002: =D1002*EXP(_xlfn.NORM.INV(RAND(),'Projection Engine'!$C$8-(Volatility^2/2),Volatility)) -> 69.536925 | F1002: =E1002*EXP(_xlfn.NORM.INV(RAND(),'Projection Engine'!$C$8-(Volatility^2/2),Volatility)) -> 67.72639 | G1002: =F1002*EXP(_xlfn.NORM.INV(RAND(),'Projection Engine'!$C$8-(Volatility^2/2),Volatility)) -> 61.581947 | H1002: =G1002*EXP(_xlfn.NORM.INV(RAND(),'Projection Engine'!$C$8-(Volatility^2/2),Volatility)) -> 97.673678 | I1002: =H1002*EXP(_xlfn.NORM.INV(RAND(),'Projection Engine'!$C$8-(Volatility^2/2),Volatility)) -> 122.88802 | J1002: =I1002*EXP(_xlfn.NORM.INV(RAND(),'Projection Engine'!$C$8-(Volatility^2/2),Volatility)) -> 118.86369 | K1002: =J1002*EXP(_xlfn.NORM.INV(RAND(),'Projection Engine'!$C$8-(Volatility^2/2),Volatility)) -> 109.54425 | ... AG1002: =AF1002*EXP(_xlfn.NORM.INV(RAND(),'Projection Engine'!$C$8-(Volatility^2/2),Volatility)) -> 1654.5107
B1004: 30 Year Median | C1004: =_xlfn.PERCENTILE.INC(AG3:AG1002,0.5) -> 612.15406
B1005: 30 Year 10th Percentile | C1005: =_xlfn.PERCENTILE.INC(AG2:AG1002,0.1) -> 47.269311
B1006: 30 Year 90th Percentile | C1006: =_xlfn.PERCENTILE.INC(AG2:AG1002,0.9) -> 6767.2605
B1008: Median | D1008: =_xlfn.PERCENTILE.INC(D3:D1002,0.5) -> 79.526779 | E1008: =_xlfn.PERCENTILE.INC(E3:E1002,0.5) -> 88.343963 | F1008: =_xlfn.PERCENTILE.INC(F3:F1002,0.5) -> 96.082218 | G1008: =_xlfn.PERCENTILE.INC(G3:G1002,0.5) -> 103.64573 | H1008: =_xlfn.PERCENTILE.INC(H3:H1002,0.5) -> 106.17016 | I1008: =_xlfn.PERCENTILE.INC(I3:I1002,0.5) -> 117.37101 | J1008: =_xlfn.PERCENTILE.INC(J3:J1002,0.5) -> 121.74092 | K1008: =_xlfn.PERCENTILE.INC(K3:K1002,0.5) -> 132.19413 | ... M1008: =_xlfn.PERCENTILE.INC(M3:M1002,0.5) -> 149.42329
B1009: 10th Percentile | D1009: =_xlfn.PERCENTILE.INC(D3:D1002,0.1) -> 51.283789 | E1009: =_xlfn.PERCENTILE.INC(E3:E1002,0.1) -> 45.219936 | F1009: =_xlfn.PERCENTILE.INC(F3:F1002,0.1) -> 42.648256 | G1009: =_xlfn.PERCENTILE.INC(G3:G1002,0.1) -> 40.495988 | H1009: =_xlfn.PERCENTILE.INC(H3:H1002,0.1) -> 40.019591 | I1009: =_xlfn.PERCENTILE.INC(I3:I1002,0.1) -> 42.460586 | J1009: =_xlfn.PERCENTILE.INC(J3:J1002,0.1) -> 40.536313 | K1009: =_xlfn.PERCENTILE.INC(K3:K1002,0.1) -> 38.410817 | ... M1009: =_xlfn.PERCENTILE.INC(M3:M1002,0.1) -> 35.605538
B1010: 90th Percentile | D1010: =_xlfn.PERCENTILE.INC(D3:D1002,0.9) -> 124.12431 | E1010: =_xlfn.PERCENTILE.INC(E3:E1002,0.9) -> 156.70324 | F1010: =_xlfn.PERCENTILE.INC(F3:F1002,0.9) -> 201.80997 | G1010: =_xlfn.PERCENTILE.INC(G3:G1002,0.9) -> 247.56909 | H1010: =_xlfn.PERCENTILE.INC(H3:H1002,0.9) -> 287.32386 | I1010: =_xlfn.PERCENTILE.INC(I3:I1002,0.9) -> 331.70961 | J1010: =_xlfn.PERCENTILE.INC(J3:J1002,0.9) -> 375.71114 | K1010: =_xlfn.PERCENTILE.INC(K3:K1002,0.9) -> 455.75936 | ... M1010: =_xlfn.PERCENTILE.INC(M3:M1002,0.9) -> 658.09017
B1012: CHART DATA
B1013: Median | D1013: 79.636785 | E1013: 85.008433 | F1013: 88.841888 | G1013: 97.213395 | H1013: 102.49886 | I1013: 115.24438 | J1013: 121.36052 | K1013: 131.76252 | L1013: 139.88172 | M1013: 157.47695
B1014: 10th Percentile | D1014: 51.501168 | E1014: 46.396674 | F1014: 44.267856 | G1014: 42.037339 | H1014: 41.712331 | I1014: 39.118157 | J1014: 37.119354 | K1014: 38.286388 | L1014: 36.637985 | M1014: 38.480672
B1015: 90th Percentile | D1015: 122.30086 | E1015: 166.29727 | F1015: 195.8365 | G1015: 234.93147 | H1015: 288.6748 | I1015: 360.77751 | J1015: 402.85677 | K1015: 447.87149 | L1015: 561.23609 | M1015: 622.42652

Sheet Charts
B2: Historical & Model Projection Chart | Q2: Historical & Inflation-Adjusted Model Projection Chart | AH2: Forward Scenarios | AY2: Monte Carlo Outputs | BQ2: Returns Breakdown Table
BQ3: Component | BR3: Value | BS3: Notes
B4: Year | C4: Historical BBY (EOY) | D4: Projected BBY | Q4: Year | R4: Historical BBY (EOY) | S4: Inflation-Adjusted Projected BBY | AH4: Year | AI4: Historical | AJ4: Bear | AK4: Base | AL4: Bull | AY4: 10th Percentile | AZ4: Median | BA4: 90th Percentile | BB4: Year | BC4: Band Lower | BD4: Band Width | BQ4: Yearly Growth | BR4: =Return_Growth -> 0.07 | BS4: Return growth assumption
B5: 2006 | C5: 27.85 | Q5: 2006 | R5: 27.85 | AH5: 2006 | AI5: 27.85 | AY5: =Current_Level -> 75 | AZ5: =Current_Level -> 75 | BA5: =Current_Level -> 75 | BB5: 2026 | BC5: =AY5 -> 75 | BD5: =BA5-AY5 -> 0 | BQ5: Dividend Yield | BR5: =Div_Yield -> 0.051 | BS5: Best Buy annual yield
B6: 2007 | C6: 27.19 | Q6: 2007 | R6: 27.19 | AH6: 2007 | AI6: 27.19 | AY6: 51.501168 | AZ6: 79.636785 | BA6: 122.30086 | BB6: 2027 | BC6: =AY6 -> 51.501168 | BD6: =BA6-AY6 -> 70.799696 | BQ6: Valuation Change | BR6: =Valuation!C5 -> 0.010591751 | BS6: Mean reversion to historical PE
B7: 2008 | C7: 15.87 | Q7: 2008 | R7: 15.87 | AH7: 2008 | AI7: 15.87 | AY7: 46.396674 | AZ7: 85.008433 | BA7: 166.29727 | BB7: 2028 | BC7: =AY7 -> 46.396674 | BD7: =BA7-AY7 -> 119.90059 | BQ7: Nominal Return | BR7: ='Projection Engine'!C8 -> 0.13159175 | BS7: Sum of components
B8: 2009 | C8: 21.07 | Q8: 2009 | R8: 21.07 | AH8: 2009 | AI8: 21.07 | AY8: 44.267856 | AZ8: 88.841888 | BA8: 195.8365 | BB8: 2029 | BC8: =AY8 -> 44.267856 | BD8: =BA8-AY8 -> 151.56864 | BQ8: Inflation | BR8: =Inflation -> 0.024 | BS8: CPI assumption
B9: 2010 | C9: 19.85 | Q9: 2010 | R9: 19.85 | AH9: 2010 | AI9: 19.85 | AY9: 42.037339 | AZ9: 97.213395 | BA9: 234.93147 | BB9: 2030 | BC9: =AY9 -> 42.037339 | BD9: =BA9-AY9 -> 192.89413 | BQ9: Real Return | BR9: ='Projection Engine'!H4 -> 0.10507007 | BS9: Inflation-adjusted
B10: 2011 | C10: 14.31 | Q10: 2011 | R10: 14.31 | AH10: 2011 | AI10: 14.31 | AY10: 41.712331 | AZ10: 102.49886 | BA10: 288.6748 | BB10: 2031 | BC10: =AY10 -> 41.712331 | BD10: =BA10-AY10 -> 246.96247
B11: 2012 | C11: 10.1 | Q11: 2012 | R11: 10.1 | AH11: 2012 | AI11: 10.1 | AY11: 39.118157 | AZ11: 115.24438 | BA11: 360.77751 | BB11: 2032 | BC11: =AY11 -> 39.118157 | BD11: =BA11-AY11 -> 321.65935
B12: 2013 | C12: 14.96 | Q12: 2013 | R12: 14.96 | AH12: 2013 | AI12: 14.96 | AY12: 37.119354 | AZ12: 121.36052 | BA12: 402.85677 | BB12: 2033 | BC12: =AY12 -> 37.119354 | BD12: =BA12-AY12 -> 365.73741
B13: 2014 | C13: 22.9 | Q13: 2014 | R13: 22.9 | AH13: 2014 | AI13: 22.9 | AY13: 38.286388 | AZ13: 131.76252 | BA13: 447.87149 | BB13: 2034 | BC13: =AY13 -> 38.286388 | BD13: =BA13-AY13 -> 409.5851
B14: 2015 | C14: 18.88 | Q14: 2015 | R14: 18.88 | AH14: 2015 | AI14: 18.88 | AY14: 36.637985 | AZ14: 139.88172 | BA14: 561.23609 | BB14: 2035 | BC14: =AY14 -> 36.637985 | BD14: =BA14-AY14 -> 524.5981
B15: 2016 | C15: 31.47 | Q15: 2016 | R15: 31.47 | AH15: 2016 | AI15: 31.47 | AY15: 38.480672 | AZ15: 157.47695 | BA15: 622.42652 | BB15: 2036 | BC15: =AY15 -> 38.480672 | BD15: =BA15-AY15 -> 583.94585
B16: 2017 | C16: 52.94 | Q16: 2017 | R16: 52.94 | AH16: 2017 | AI16: 52.94
B17: 2018 | C17: 44.04 | Q17: 2018 | R17: 44.04 | AH17: 2018 | AI17: 44.04
B18: 2019 | C18: 64.76 | Q18: 2019 | R18: 64.76 | AH18: 2019 | AI18: 64.76
B19: 2020 | C19: 85.45 | Q19: 2020 | R19: 85.45 | AH19: 2020 | AI19: 85.45
B20: 2021 | C20: 79.97 | Q20: 2021 | R20: 79.97 | AH20: 2021 | AI20: 79.97
B21: 2022 | C21: 74.68 | Q21: 2022 | R21: 74.68 | AH21: 2022 | AI21: 74.68
B22: 2023 | C22: 64.09 | Q22: 2023 | R22: 64.09 | AH22: 2023 | AI22: 64.09
B23: 2024 | C23: 79.2 | Q23: 2024 | R23: 79.2 | AH23: 2024 | AI23: 79.2
B24: 2025 | C24: 63.28 | Q24: 2025 | R24: 63.28 | AH24: 2025 | AI24: 63.28
A25: *June 2026 | B25: 2026 | C25: 75 | Q25: 2026 | R25: 75 | AH25: 2026 | AI25: 75
B26: 2027 | C26: =D26 -> 84.869381 | D26: {='Projection Engine'!F5:F14} -> 84.869381 | Q26: 2027 | R26: =S26 -> 82.880255 | S26: {='Projection Engine'!J5:J14} -> 82.880255 | AH26: 2027 | AI26: =AK26 -> 84.869381 | AJ26: {=Scenarios!F10:F19} -> 82.575 | AK26: {=Scenarios!G10:G19} -> 84.869381 | AL26: {=Scenarios!H10:H19} -> 87.075
B27: 2028 | D27: 96.037492 | Q27: 2028 | S27: 91.588489 | AH27: 2028 | AJ27: 90.915075 | AK27: 96.037492 | AL27: 101.09408
B28: 2029 | D28: 108.67523 | Q28: 2029 | S28: 101.2117 | AH28: 2029 | AJ28: 100.0975 | AK28: 108.67523 | AL28: 117.37022
B29: 2030 | D29: 122.976 | Q29: 2030 | S29: 111.84602 | AH29: 2030 | AJ29: 110.20734 | AK29: 122.976 | AL29: 136.26683
B30: 2031 | D30: 139.15862 | Q30: 2031 | S30: 123.59769 | AH30: 2031 | AJ30: 121.33829 | AK30: 139.15862 | AL30: 158.20579
B31: 2032 | D31: 157.47075 | Q31: 2032 | S31: 136.58411 | AH31: 2032 | AJ31: 133.59345 | AK31: 157.47075 | AL31: 183.67692
B32: 2033 | D32: 178.1926 | Q32: 2033 | S32: 150.93501 | AH32: 2033 | AJ32: 147.08639 | AK32: 178.1926 | AL32: 213.2489
B33: 2034 | D33: 201.64128 | Q33: 2034 | S33: 166.79376 | AH33: 2034 | AJ33: 161.94212 | AK33: 201.64128 | AL33: 247.58197
B34: 2035 | D34: 228.17561 | Q34: 2035 | S34: 184.31879 | AH34: 2035 | AJ34: 178.29827 | AK34: 228.17561 | AL34: 287.44267
B35: 2036 | D35: 258.20164 | Q35: 2036 | S35: 203.68518 | AH35: 2036 | AJ35: 196.3064 | AK35: 258.20164 | AL35: 333.72094
B40: Monte Carlo Simulation Results Outputs
C41: Year 0 | D41: Year 1 | E41: Year 2 | F41: Year 3 | G41: Year 4 | H41: Year 5 | I41: Year 6 | J41: Year 7 | K41: Year 8 | L41: Year 9 | M41: Year 10 | N41: Year 11 | O41: Year 12 | P41: Year 13 | Q41: Year 14 | R41: Year 15 | S41: Year 16 | T41: Year 17 | U41: Year 18 | V41: Year 19 | W41: Year 20 | X41: Year 21 | Y41: Year 22 | Z41: Year 23 | AA41: Year 24 | AB41: Year 25 | AC41: Year 26 | AD41: Year 27 | AE41: Year 28 | AF41: Year 29 | AG41: Year 30 | AI41: 10 Year Results
B42: Simulation 1 | C42: 75 | D42: 118.06343 | E42: 116.65764 | F42: 97.862926 | G42: 66.907556 | H42: 61.528333 | I42: 75.882787 | J42: 63.678667 | K42: 72.514256 | L42: 113.33931 | M42: 91.998378 | N42: 65.173734 | O42: 47.882886 | P42: 102.47451 | Q42: 126.83205 | R42: 271.0486 | S42: 249.10936 | T42: 251.68945 | U42: 264.99886 | V42: 448.8716 | W42: 436.84076 | X42: 287.52978 | Y42: 574.75205 | Z42: 474.09925 | AA42: 620.69535 | AB42: 780.90877 | AC42: 615.90592 | AD42: 990.34683 | AE42: 708.79198 | AF42: 1252.5068 | AG42: 1140.4225 | AI42: 91.998378
B43: Simulation 2 | C43: 75 | D43: 138.31436 | E43: 201.09581 | F43: 203.93436 | G43: 259.86525 | H43: 184.66823 | I43: 103.71136 | J43: 119.57639 | K43: 74.993651 | L43: 64.35816 | M43: 104.92316 | N43: 121.66556 | O43: 107.93882 | P43: 62.793513 | Q43: 125.54534 | R43: 159.42931 | S43: 126.14297 | T43: 186.94344 | U43: 289.80091 | V43: 233.47501 | W43: 192.40154 | X43: 272.99131 | Y43: 258.59551 | Z43: 230.49903 | AA43: 163.20093 | AB43: 284.56439 | AC43: 310.90514 | AD43: 333.13593 | AE43: 567.87306 | AF43: 429.29167 | AG43: 361.90438 | AI43: 104.92316
B44: Simulation 3 | C44: 75 | D44: 94.538771 | E44: 128.22101 | F44: 90.758411 | G44: 140.87664 | H44: 88.806711 | I44: 87.135414 | J44: 31.782944 | K44: 31.875201 | L44: 27.108572 | M44: 26.098973 | N44: 31.941175 | O44: 29.81418 | P44: 19.632257 | Q44: 19.685729 | R44: 17.69255 | S44: 18.294466 | T44: 17.224085 | U44: 19.348673 | V44: 19.705321 | W44: 28.139885 | X44: 27.597322 | Y44: 35.286356 | Z44: 35.195712 | AA44: 30.032617 | AB44: 38.563615 | AC44: 55.188133 | AD44: 31.51769 | AE44: 35.426777 | AF44: 63.997046 | AG44: 46.904334 | AI44: 26.098973
B45: Simulation 4 | C45: 75 | D45: 60.514555 | E45: 87.55246 | F45: 85.261423 | G45: 95.21397 | H45: 47.627065 | I45: 48.284216 | J45: 31.579952 | K45: 21.63733 | L45: 22.603 | M45: 42.456811 | N45: 60.050475 | O45: 78.223265 | P45: 50.155029 | Q45: 55.276231 | R45: 109.69182 | S45: 85.711161 | T45: 168.63429 | U45: 125.10721 | V45: 129.42359 | W45: 147.24585 | X45: 236.21055 | Y45: 215.45245 | Z45: 183.80808 | AA45: 288.17971 | AB45: 210.25014 | AC45: 324.86245 | AD45: 232.9382 | AE45: 145.00794 | AF45: 224.81778 | AG45: 357.69885 | AI45: 42.456811
...

Sheet Export
